File: Tensile Testing/Data/Aluminium_Monatonic.csv
1,Time,Displacement,Force,120Ohm SG Adapter A,Strain 2
,(s),(mm),(kN),(%),(%)
"","0.0000","0.0000","0.0002","0.0000","-0.0009"
"","0.3000","0.0077","0.0032","0.0000","-0.0007"
"","0.6000","0.0307","0.0069","0.0000","-0.0005"
"","0.9000","0.0498","0.0091","0.0000","-0.0003"
"","1.2000","0.0689","0.0117","-0.0001","-0.0004"
"","1.5000","0.0877","0.0153","0.0000","-0.0008"
"","1.8000","0.1073","0.0196","0.0000","-0.0010"
"","2.1000","0.1260","0.0227","0.0000","-0.0014"
"","2.4000","0.1447","0.0237","0.0000","-0.0021"
"","2.7000","0.1645","0.0274","0.0001","-0.0026"
"","3.0000","0.1830","0.0337","0.0000","-0.0036"
"","3.3000","0.2023","0.0389","0.0000","-0.0042"
"","3.6000","0.2215","0.0511","0.0000","-0.0042"
"","3.9000","0.2401","0.0867","0.0000","-0.0005"
"","4.2000","0.2598","0.1329","-0.0001","0.0006"
"","4.5000","0.2783","0.1869","0.0000","0.0015"
"","4.8000","0.2973","0.2447","0.0001","0.0021"
"","5.1000","0.3168","0.3036","-0.0001","0.0035"
"","5.4000","0.3356","0.3587","0.0000","0.0045"
"","5.7000","0.3547","0.4132","0.0000","0.0057"
"","6.0000","0.3735","0.4638","0.0000","0.0061"
"","6.3000","0.3926","0.5139","0.0000","0.0069"
"","6.6000","0.4122","0.5643","0.0000","0.0074"
"","6.9000","0.4308","0.6089","-0.0001","0.0078"
"","7.2000","0.4497","0.6530","0.0000","0.0082"
"","7.5000","0.4686","0.6985","0.0000","0.0088"
"","7.8000","0.4881","0.7434","0.0000","0.0089"
"","8.1000","0.5072","0.7875","-0.0001","0.0096"
"","8.4000","0.5259","0.8305","0.0000","0.0100"
"","8.7000","0.5450","0.8734","0.0000","0.0105"
"","9.0000","0.5639","0.9198","0.0000","0.0112"
"","9.3000","0.5836","0.9664","0.0000","0.0120"
"","9.6000","0.6025","1.0114","0.0000","0.0128"
"","9.9000","0.6209","1.0561","0.0000","0.0138"
"","10.2000","0.6402","1.1027","0.0000","0.0149"
"","10.5000","0.6593","1.1483","0.0000","0.0161"
"","10.8000","0.6788","1.1949","0.0000","0.0170"
"","11.1000","0.6978","1.2394","0.0000","0.0183"
"","11.4000","0.7159","1.2851","0.0000","0.0193"
"","11.7000","0.7358","1.3382","0.0000","0.0207"
"","12.0000","0.7548","1.3852","0.0000","0.0223"
"","12.3000","0.7736","1.4346","0.0001","0.0235"
"","12.6000","0.7930","1.4882","0.0000","0.0252"
"","12.9000","0.8114","1.5380","-0.0001","0.0267"
"","13.2000","0.8310","1.5943","0.0000","0.0287"
"","13.5000","0.8501","1.6460","0.0000","0.0301"
"","13.8000","0.8687","1.6966","-0.0001","0.0319"
"","14.1000","0.8882","1.7555","0.0000","0.0338"
"","14.4000","0.9072","1.8108","0.0000","0.0361"
"","14.7000","0.9261","1.8645","0.0000","0.0377"
"","15.0000","0.9453","1.9206","0.0000","0.0397"
"","15.3000","0.9638","1.9754","0.0000","0.0415"
"","15.6000","0.9834","2.0353","0.0000","0.0438"
"","15.9000","1.0026","2.0941","0.0000","0.0459"
"","16.2000","1.0214","2.1481","0.0001","0.0480"
"","16.5000","1.0403","2.2072","0.0000","0.0500"
"","16.8000","1.0594","2.2704","0.0000","0.0525"
"","17.1000","1.0788","2.3321","0.0000","0.0550"
"","17.4000","1.0975","2.3917","0.0000","0.0573"
"","17.7000","1.1166","2.4532","0.0000","0.0598"
"","18.0000","1.1355","2.5143","0.0000","0.0622"
"","18.3000","1.1548","2.5807","0.0001","0.0650"
"","18.6000","1.1742","2.6428","0.0000","0.0675"
"","18.9000","1.1925","2.7001","0.0000","0.0699"
"","19.2000","1.2118","2.7655","0.0000","0.0724"
"","19.5000","1.2308","2.8290","0.0000","0.0754"
"","19.8000","1.2500","2.8932","0.0000","0.0783"
"","20.1000","1.2694","2.9583","-0.0001","0.0809"
"","20.4000","1.2877","3.0161","0.0000","0.0836"
"","20.7000","1.3068","3.0845","0.0000","0.0868"
"","21.0000","1.3266","3.1531","0.0000","0.0899"
"","21.3000","1.3451","3.2152","0.0000","0.0929"
"","21.6000","1.3641","3.2810","0.0000","0.0956"
"","21.9000","1.3832","3.3471","-0.0001","0.0986"
"","22.2000","1.4021","3.4140","0.0000","0.1019"
"","22.5000","1.4218","3.4830","0.0000","0.1049"
"","22.8000","1.4403","3.5454","0.0000","0.1079"
"","23.1000","1.4593","3.6120","0.0000","0.1112"
"","23.4000","1.4788","3.6819","0.0000","0.1144"
"","23.7000","1.4978","3.7489","-0.0001","0.1176"
"","24.0000","1.5168","3.8150","0.0000","0.1208"
"","24.3000","1.5357","3.8817","0.0000","0.1241"
"","24.6000","1.5547","3.9485","-0.0001","0.1274"
"","24.9000","1.5741","4.0196","0.0000","0.1307"
"","25.2000","1.5928","4.0863","0.0000","0.1338"
"","25.5000","1.6118","4.1527","0.0000","0.1371"
"","25.8000","1.6309","4.2238","-0.0001","0.1408"
"","26.1000","1.6500","4.2947","-0.0001","0.1442"
"","26.4000","1.6693","4.3646","0.0000","0.1478"
"","26.7000","1.6880","4.4326","-0.0001","0.1512"
"","27.0000","1.7071","4.5012","0.0000","0.1547"
"","27.3000","1.7261","4.5731","0.0000","0.1583"
"","27.6000","1.7456","4.6482","-0.0001","0.1621"
"","27.9000","1.7642","4.7132","0.0000","0.1654"
"","28.2000","1.7829","4.7833","0.0000","0.1691"
"","28.5000","1.8026","4.8591","-0.0001","0.1729"
"","28.8000","1.8214","4.9300","0.0000","0.1768"
"","29.1000","1.8407","5.0064","0.0000","0.1805"
"","29.4000","1.8596","5.0743","-0.0001","0.1843"
"","29.7000","1.8781","5.1436","-0.0001","0.1880"
"","30.0000","1.8981","5.2247","0.0000","0.1924"
"","30.3000","1.9169","5.2942","0.0000","0.1963"
"","30.6000","1.9355","5.3662","0.0000","0.2004"
"","30.9000","1.9550","5.4410","0.0000","0.2043"
"","31.2000","1.9735","5.5109","0.0000","0.2082"
"","31.5000","1.9933","5.5914","-0.0001","0.2128"
"","31.8000","2.0123","5.6633","0.0000","0.2171"
"","32.1000","2.0306","5.7324","0.0000","0.2209"
"","32.4000","2.0503","5.8114","0.0000","0.2255"
"","32.7000","2.0692","5.8846","-0.0001","0.2298"
"","33.0000","2.0882","5.9587","0.0000","0.2342"
"","33.3000","2.1075","6.0337","-0.0001","0.2390"
"","33.6000","2.1258","6.1032","-0.0001","0.2435"
"","33.9000","2.1456","6.1820","-0.0001","0.2482"
"","34.2000","2.1646","6.2570","0.0000","0.2530"
"","34.5000","2.1834","6.3285","-0.0001","0.2577"
"","34.8000","2.2024","6.4010","0.0000","0.2626"
"","35.1000","2.2214","6.4773","-0.0001","0.2678"
"","35.4000","2.2408","6.5522","0.0000","0.2730"
"","35.7000","2.2596","6.6235","0.0000","0.2779"
"","36.0000","2.2786","6.6970","0.0001","0.2831"
"","36.3000","2.2976","6.7687","-0.0001","0.2882"
"","36.6000","2.3168","6.8453","0.0000","0.2940"
"","36.9000","2.3361","6.9178","-0.0001","0.2994"
"","37.2000","2.3545","6.9846","0.0000","0.3048"
"","37.5000","2.3740","7.0633","-0.0001","0.3106"
"","37.8000","2.3932","7.1346","0.0000","0.3166"
"","38.1000","2.4119","7.2053","0.0000","0.3228"
"","38.4000","2.4312","7.2780","-0.0001","0.3287"
"","38.7000","2.4497","7.3417","-0.0001","0.3346"
"","39.0000","2.4692","7.4192","0.0001","0.3413"
"","39.3000","2.4887","7.4912","-0.0001","0.3482"
"","39.6000","2.5069","7.5549","0.0000","0.3545"
"","39.9000","2.5264","7.6267","0.0000","0.3617"
"","40.2000","2.5453","7.6921","0.0000","0.3687"
"","40.5000","2.5643","7.7631","0.0000","0.3764"
"","40.8000","2.5840","7.8328","0.0000","0.3841"
"","41.1000","2.6022","7.8929","0.0000","0.3916"
"","41.4000","2.6214","7.9588","0.0000","0.3998"
"","41.7000","2.6409","8.0257","0.0000","0.4085"
"","42.0000","2.6596","8.0894","0.0000","0.4173"
"","42.3000","2.6789","8.1514","-0.0001","0.4264"
"","42.6000","2.6975","8.2088","0.0000","0.4357"
"","42.9000","2.7167","8.2708","0.0000","0.4456"
"","43.2000","2.7362","8.3312","0.0000","0.4562"
"","43.5000","2.7548","8.3849","0.0000","0.4668"
"","43.8000","2.7738","8.4384","0.0000","0.4781"
"","44.1000","2.7928","8.4920","-0.0001","0.4900"
"","44.4000","2.8123","8.5480","-0.0001","0.5027"
"","44.7000","2.8313","8.5940","0.0000","0.5162"
"","45.0000","2.8500","8.6402","0.0000","0.5302"
"","45.3000","2.8690","8.6804","-0.0001","0.5454"
"","45.6000","2.8882","8.7240","0.0000","0.5620"
"","45.9000","2.9077","8.7677","0.0000","0.5794"
"","46.2000","2.9263","8.7936","-0.0001","0.5976"
"","46.5000","2.9451","8.8279","0.0000","0.6167"
"","46.8000","2.9646","8.8611","0.0000","0.6374"
"","47.1000","2.9834","8.8867","-0.0001","0.6583"
"","47.4000","3.0028","8.9201","0.0000","0.6796"
"","47.7000","3.0215","8.9378","0.0000","0.7015"
"","48.0000","3.0402","8.9621","0.0000","0.7236"
"","48.3000","3.0601","8.9932","-0.0001","0.7469"
"","48.6000","3.0787","9.0082","-0.0001","0.7741"
"","48.9000","3.0976","9.0323","0.0000","0.7966"
"","49.2000","3.1171","9.0531","0.0000","0.8203"
"","49.5000","3.1357","9.0720","0.0000","0.8431"
"","49.8000","3.1553","9.0971","-0.0001","0.8668"
"","50.1000","3.1739","9.1099","0.0000","0.8905"
"","50.4000","3.1926","9.1276","0.0000","0.9135"
"","50.7000","3.2125","9.1520","0.0000","0.9384"
"","51.0000","3.2313","9.1671","-0.0001","0.9622"
"","51.3000","3.2502","9.1847","-0.0001","0.9862"
"","51.6000","3.2693","9.1985","0.0000","1.0106"
"","51.9000","3.2879","9.2147","0.0000","1.0344"
"","52.2000","3.3078","9.2368","-0.0001","1.0595"
"","52.5000","3.3265","9.2495","0.0000","1.0838"
"","52.8000","3.3453","9.2627","-0.0001","1.1079"
"","53.1000","3.3644","9.2778","-0.0001","1.1325"
"","53.4000","3.3835","9.2964","-0.0001","1.1569"
"","53.7000","3.4031","9.3139","0.0001","1.1828"
"","54.0000","3.4216","9.3226","0.0000","1.2067"
"","54.3000","3.4405","9.3383","-0.0001","1.2306"
"","54.6000","3.4596","9.3513","-0.0001","1.2555"
"","54.9000","3.4789","9.3700","0.0000","1.2800"
"","55.2000","3.4982","9.3850","-0.0001","1.3046"
"","55.5000","3.5166","9.3914","-0.0001","1.3283"
"","55.8000","3.5360","9.4115","-0.0001","1.3528"
"","56.1000","3.5552","9.4250","-0.0001","1.3775"
"","56.4000","3.5740","9.4381","0.0000","1.4013"
"","56.7000","3.5933","9.4524","-0.0001","1.4259"
"","57.0000","3.6117","9.4586","0.0000","1.4496"
"","57.3000","3.6312","9.4803","-0.0001","1.4737"
"","57.6000","3.6506","9.4927","0.0000","1.4982"
"","57.9000","3.6689","9.5007","0.0000","1.5219"
"","58.2000","3.6886","9.5191","-0.0001","1.5464"
"","58.5000","3.7074","9.5278","0.0000","1.5705"
"","58.8000","3.7265","9.5450","-0.0001","1.5942"
"","59.1000","3.7459","9.5575","0.0000","1.6190"
"","59.4000","3.7640","9.5630","0.0000","1.6426"
"","59.7000","3.7836","9.5809","-0.0001","1.6671"
"","60.0000","3.8029","9.5932","0.0000","1.6915"
"","60.3000","3.8216","9.6055","0.0000","1.7158"
"","60.6000","3.8409","9.6190","-0.0001","1.7403"
"","60.9000","3.8594","9.6264","-0.0001","1.7640"
"","61.2000","3.8789","9.6434","0.0001","1.7882"
"","61.5000","3.8983","9.6566","0.0000","1.8129"
"","61.8000","3.9168","9.6653","-0.0001","1.8367"
"","62.1000","3.9359","9.6774","0.0000","1.8614"
"","62.4000","3.9549","9.6883","0.0000","1.8853"
"","62.7000","3.9744","9.7060","-0.0001","1.9106"
"","63.0000","3.9934","9.7146","0.0000","1.9365"
"","63.3000","4.0121","9.7242","-0.0001","1.9603"
"","63.6000","4.0312","9.7374","-0.0001","1.9841"
"","63.9000","4.0504","9.7497","0.0000","2.0080"
"","64.2000","4.0698","9.7651","0.0000","2.0322"
"","64.5000","4.0882","9.7692","-0.0001","2.0559"
"","64.8000","4.1075","9.7846","-0.0001","2.0806"
"","65.1000","4.1267","9.7968","0.0000","2.1042"
"","65.4000","4.1456","9.8060","-0.0001","2.1277"
"","65.7000","4.1649","9.8219","-0.0001","2.1514"
"","66.0000","4.1836","9.8271","0.0000","2.1751"
"","66.3000","4.2023","9.8374","-0.0001","2.1982"
"","66.6000","4.2221","9.8558","-0.0001","2.2222"
"","66.9000","4.2406","9.8589","-0.0001","2.2455"
"","67.2000","4.2598","9.8745","0.0000","2.2689"
"","67.5000","4.2791","9.8857","-0.0001","2.2928"
"","67.8000","4.2976","9.8929","-0.0001","2.3157"
"","68.1000","4.3174","9.9116","0.0000","2.3403"
"","68.4000","4.3361","9.9161","-0.0001","2.3638"
"","68.7000","4.3546","9.9248","0.0000","2.3868"
"","69.0000","4.3746","9.9431","0.0000","2.4113"
"","69.3000","4.3932","9.9503","-0.0001","2.4345"
"","69.6000","4.4122","9.9610","-0.0001","2.4581"
"","69.9000","4.4313","9.9702","-0.0001","2.4818"
"","70.2000","4.4499","9.9792","-0.0001","2.5048"
"","70.5000","4.4699","9.9973","-0.0001","2.5294"
"","70.8000","4.4886","10.0043","-0.0001","2.5534"
"","71.1000","4.5073","10.0124","0.0000","2.5768"
"","71.4000","4.5267","10.0246","-0.0001","2.6005"
"","71.7000","4.5456","10.0365","-0.0001","2.6240"
"","72.0000","4.5648","10.0471","-0.0001","2.6478"
"","72.3000","4.5837","10.0547","-0.0001","2.6714"
"","72.6000","4.6026","10.0649","-0.0001","2.6950"
"","72.9000","4.6220","10.0775","0.0000","2.7190"
"","73.2000","4.6409","10.0888","-0.0001","2.7423"
"","73.5000","4.6600","10.0973","-0.0001","2.7659"
"","73.8000","4.6787","10.1033","0.0000","2.7894"
"","74.1000","4.6979","10.1180","-0.0001","2.8130"
"","74.4000","4.7174","10.1299","-0.0002","2.8368"
"","74.7000","4.7360","10.1371","0.0000","2.8602"
"","75.0000","4.7550","10.1460","0.0000","2.8837"
"","75.3000","4.7737","10.1515","-0.0001","2.9068"
"","75.6000","4.7934","10.1694","-0.0001","2.9308"
"","75.9000","4.8127","10.1806","-0.0001","2.9544"
"","76.2000","4.8310","10.1839","0.0000","2.9777"
"","76.5000","4.8504","10.1973","-0.0001","3.0019"
"","76.8000","4.8694","10.2050","0.0000","3.0257"
"","77.1000","4.8886","10.2178","-0.0001","3.0492"
"","77.4000","4.9080","10.2297","-0.0002","3.0730"
"","77.7000","4.9261","10.2307","0.0000","3.0958"
"","78.0000","4.9457","10.2463","-0.0001","3.1196"
"","78.3000","4.9650","10.2563","-0.0001","3.1436"
"","78.6000","4.9836","10.2638","0.0000","3.1667"
"","78.9000","5.0033","10.2789","-0.0001","3.1905"
"","79.2000","5.0215","10.2797","-0.0001","3.2138"
"","79.5000","5.0409","10.2944","-0.0001","3.2376"
"","79.8000","5.0604","10.3058","0.0000","3.2616"
"","80.1000","5.0787","10.3093","-0.0001","3.2843"
"","80.4000","5.0981","10.3225","0.0000","3.3081"
"","80.7000","5.1171","10.3309","0.0000","3.3315"
"","81.0000","5.1362","10.3409","-0.0001","3.3555"
"","81.3000","5.1554","10.3498","-0.0001","3.3791"
"","81.6000","5.1740","10.3569","0.0000","3.4024"
"","81.9000","5.1934","10.3685","0.0000","3.4262"
"","82.2000","5.2125","10.3773","-0.0002","3.4502"
"","82.5000","5.2316","10.3887","0.0000","3.4738"
"","82.8000","5.2503","10.3930","0.0000","3.4984"
"","83.1000","5.2693","10.4024","-0.0001","3.5244"
"","83.4000","5.2888","10.4159","-0.0001","3.5482"
"","83.7000","5.3076","10.4217","0.0000","3.5717"
"","84.0000","5.3266","10.4316","-0.0001","3.5951"
"","84.3000","5.3456","10.4381","-0.0001","3.6192"
"","84.6000","5.3646","10.4481","0.0000","3.6426"
"","84.9000","5.3843","10.4627","-0.0001","3.6665"
"","85.2000","5.4026","10.4627","-0.0001","3.6894"
"","85.5000","5.4217","10.4749","0.0000","3.7129"
"","85.8000","5.4411","10.4860","-0.0001","3.7367"
"","86.1000","5.4599","10.4924","-0.0001","3.7599"
"","86.4000","5.4795","10.5055","0.0000","3.7841"
"","86.7000","5.4980","10.5082","-0.0001","3.8071"
"","87.0000","5.5168","10.5164","-0.0001","3.8302"
"","87.3000","5.5367","10.5319","-0.0001","3.8546"
"","87.6000","5.5552","10.5359","0.0000","3.8782"
"","87.9000","5.5744","10.5465","-0.0001","3.9020"
"","88.2000","5.5935","10.5533","-0.0001","3.9253"
"","88.5000","5.6119","10.5581","0.0000","3.9483"
"","88.8000","5.6320","10.5758","-0.0001","3.9727"
"","89.1000","5.6506","10.5789","-0.0001","3.9959"
"","89.4000","5.6693","10.5852","0.0000","4.0191"
"","89.7000","5.6887","10.5957","-0.0001","4.0427"
"","90.0000","5.7077","10.6051","-0.0001","4.0667"
"","90.3000","5.7271","10.6154","-0.0001","4.0916"
"","90.6000","5.7457","10.6193","-0.0001","4.1185"
"","90.9000","5.7645","10.6272","-0.0001","4.1419"
"","91.2000","5.7840","10.6377","0.0000","4.1654"
"","91.5000","5.8031","10.6476","0.0000","4.1892"
"","91.8000","5.8220","10.6539","-0.0001","4.2128"
"","92.1000","5.8409","10.6598","-0.0001","4.2363"
"","92.4000","5.8601","10.6704","0.0000","4.2600"
"","92.7000","5.8793","10.6782","-0.0001","4.2836"
"","93.0000","5.8981","10.6861","-0.0001","4.3069"
"","93.3000","5.9173","10.6948","-0.0001","4.3308"
"","93.6000","5.9361","10.6980","-0.0001","4.3540"
"","93.9000","5.9555","10.7126","-0.0001","4.3779"
"","94.2000","5.9745","10.7179","-0.0001","4.4016"
"","94.5000","5.9930","10.7220","0.0000","4.4251"
"","94.8000","6.0126","10.7349","-0.0001","4.4489"
"","95.1000","6.0315","10.7398","0.0000","4.4728"
"","95.4000","6.0506","10.7508","-0.0001","4.4959"
"","95.7000","6.0699","10.7589","-0.0001","4.5199"
"","96.0000","6.0881","10.7591","0.0000","4.5432"
"","96.3000","6.1078","10.7741","0.0000","4.5671"
"","96.6000","6.1271","10.7819","-0.0001","4.5910"
"","96.9000","6.1455","10.7851","0.0000","4.6138"
"","97.2000","6.1650","10.7963","-0.0001","4.6381"
"","97.5000","6.1835","10.7989","0.0000","4.6614"
"","97.8000","6.2033","10.8131","-0.0001","4.6855"
"","98.1000","6.2224","10.8207","-0.0001","4.7098"
"","98.4000","6.2406","10.8218","-0.0001","4.7329"
"","98.7000","6.2602","10.8329","-0.0001","4.7568"
"","99.0000","6.2793","10.8409","-0.0001","4.7805"
"","99.3000","6.2984","10.8488","0.0000","4.8041"
"","99.6000","6.3175","10.8560","-0.0001","4.8278"
"","99.9000","6.3360","10.8596","-0.0001","4.8514"
"","100.2000","6.3554","10.8707","-0.0001","4.8754"
"","100.5000","6.3748","10.8793","-0.0001","4.8995"
"","100.8000","6.3936","10.8852","-0.0001","4.9229"
"","101.1000","6.4123","10.8889","-0.0001","4.9461"
"","101.4000","6.4313","10.8968","-0.0001","4.9699"
"","101.7000","6.4508","10.9080","-0.0001","4.9942"
"","102.0000","6.4697","10.9125","0.0000","5.0183"
"","102.3000","6.4887","10.9205","-0.0001","5.0417"
"","102.6000","6.5077","10.9257","-0.0001","5.0656"
"","102.9000","6.5266","10.9325","0.0000","5.0892"
"","103.2000","6.5463","10.9457","0.0000","5.1133"
"","103.5000","6.5647","10.9440","-0.0001","5.1366"
"","103.8000","6.5838","10.9537","0.0000","5.1603"
"","104.1000","6.6033","10.9636","-0.0001","5.1846"
"","104.4000","6.6219","10.9681","-0.0001","5.2081"
"","104.7000","6.6415","10.9799","-0.0001","5.2323"
"","105.0000","6.6599","10.9792","0.0000","5.2557"
"","105.3000","6.6790","10.9887","-0.0001","5.2794"
"","105.6000","6.6988","11.0023","-0.0001","5.3035"
"","105.9000","6.7172","11.0023","0.0000","5.3272"
"","106.2000","6.7365","11.0110","-0.0001","5.3511"
"","106.5000","6.7552","11.0143","-0.0001","5.3747"
"","106.8000","6.7742","11.0220","0.0000","5.4001"
"","107.1000","6.7941","11.0361","-0.0001","5.4260"
"","107.4000","6.8123","11.0341","-0.0001","5.4525"
"","107.7000","6.8312","11.0401","-0.0001","5.4768"
"","108.0000","6.8508","11.0500","-0.0001","5.5019"
"","108.3000","6.8697","11.0573","-0.0001","5.5258"
"","108.6000","6.8891","11.0666","-0.0001","5.5502"
"","108.9000","6.9076","11.0676","0.0000","5.5740"
"","109.2000","6.9267","11.0749","-0.0001","5.5978"
"","109.5000","6.9461","11.0845","-0.0001","5.6224"
"","109.8000","6.9653","11.0921","0.0000","5.6467"
"","110.1000","6.9840","11.0954","-0.0001","5.6712"
"","110.4000","7.0029","11.0993","-0.0002","5.6953"
"","110.7000","7.0223","11.1111","0.0000","5.7204"
"","111.0000","7.0414","11.1161","-0.0001","5.7452"
"","111.3000","7.0602","11.1220","-0.0001","5.7701"
"","111.6000","7.0792","11.1268","-0.0001","5.7950"
"","111.9000","7.0981","11.1306","-0.0001","5.8194"
"","112.2000","7.1176","11.1433","-0.0001","5.8434"
"","112.5000","7.1365","11.1465","-0.0001","5.8674"
"","112.8000","7.1551","11.1498","0.0000","5.8908"
"","113.1000","7.1747","11.1603","-0.0001","5.9152"
"","113.4000","7.1935","11.1630","-0.0001","5.9389"
"","113.7000","7.2127","11.1729","0.0000","5.9630"
"","114.0000","7.2318","11.1777","-0.0001","5.9870"
"","114.3000","7.2502","11.1785","-0.0001","6.0106"
"","114.6000","7.2700","11.1920","-0.0001","6.0350"
"","114.9000","7.2890","11.1958","-0.0001","6.0589"
"","115.2000","7.3076","11.2002","-0.0001","6.0826"
"","115.5000","7.3271","11.2090","-0.0001","6.1069"
"","115.8000","7.3456","11.2099","0.0000","6.1304"
"","116.1000","7.3653","11.2224","-0.0001","6.1546"
"","116.4000","7.3843","11.2267","-0.0001","6.1787"
"","116.7000","7.4026","11.2266","-0.0001","6.2020"
"","117.0000","7.4223","11.2377","-0.0002","6.2265"
"","117.3000","7.4414","11.2443","-0.0001","6.2508"
"","117.6000","7.4603","11.2501","-0.0001","6.2748"
"","117.9000","7.4794","11.2545","-0.0001","6.2990"
"","118.2000","7.4980","11.2574","-0.0001","6.3228"
"","118.5000","7.5176","11.2678","-0.0001","6.3471"
"","118.8000","7.5367","11.2736","-0.0001","6.3713"
"","119.1000","7.5555","11.2772","-0.0001","6.3950"
"","119.4000","7.5746","11.2822","0.0000","6.4193"
"","119.7000","7.5935","11.2887","-0.0001","6.4435"
"","120.0000","7.6130","11.2970","-0.0002","6.4678"
"","120.3000","7.6317","11.2995","0.0000","6.4918"
"","120.6000","7.6508","11.3061","-0.0001","6.5159"
"","120.9000","7.6698","11.3093","-0.0001","6.5402"
"","121.2000","7.6889","11.3177","-0.0001","6.5644"
"","121.5000","7.7083","11.3258","-0.0001","6.5891"
"","121.8000","7.7266","11.3237","-0.0001","6.6127"
"","122.1000","7.7458","11.3318","-0.0001","6.6371"
"","122.4000","7.7653","11.3401","-0.0001","6.6617"
"","122.7000","7.7840","11.3430","-0.0001","6.6858"
"","123.0000","7.8035","11.3524","-0.0002","6.7106"
"","123.3000","7.8218","11.3505","-0.0001","6.7344"
"","123.6000","7.8412","11.3599","-0.0001","6.7587"
"","123.9000","7.8608","11.3696","-0.0001","6.7836"
"","124.2000","7.8791","11.3682","-0.0001","6.8076"
"","124.5000","7.8984","11.3765","-0.0001","6.8318"
"","124.8000","7.9174","11.3796","-0.0002","6.8561"
"","125.1000","7.9363","11.3856","0.0000","6.8803"
"","125.4000","7.9561","11.3970","-0.0001","6.9055"
"","125.7000","7.9743","11.3936","-0.0001","6.9304"
"","126.0000","7.9937","11.4022","0.0000","6.9560"
"","126.3000","8.0129","11.4088","-0.0001","6.9807"
"","126.6000","8.0317","11.4130","-0.0001","7.0047"
"","126.9000","8.0512","11.4212","-0.0001","7.0295"
"","127.2000","8.0696","11.4204","-0.0001","7.0536"
"","127.5000","8.0889","11.4282","-0.0001","7.0781"
"","127.8000","8.1082","11.4352","-0.0001","7.1029"
"","128.1000","8.1271","11.4389","0.0000","7.1273"
"","128.4000","8.1460","11.4421","-0.0001","7.1516"
"","128.7000","8.1650","11.4463","-0.0001","7.1764"
"","129.0000","8.1843","11.4549","0.0000","7.2009"
"","129.3000","8.2033","11.4584","-0.0001","7.2253"
"","129.6000","8.2221","11.4620","-0.0001","7.2499"
"","129.9000","8.2412","11.4668","-0.0001","7.2746"
"","130.2000","8.2602","11.4698","-0.0001","7.2992"
"","130.5000","8.2798","11.4819","-0.0001","7.3242"
"","130.8000","8.2984","11.4812","0.0000","7.3483"
"","131.1000","8.3172","11.4845","-0.0001","7.3730"
"","131.4000","8.3366","11.4913","-0.0001","7.3981"
"","131.7000","8.3556","11.4953","-0.0001","7.4226"
"","132.0000","8.3750","11.5041","-0.0001","7.4472"
"","132.3000","8.3937","11.5051","-0.0001","7.4720"
"","132.6000","8.4123","11.5067","-0.0001","7.4963"
"","132.9000","8.4323","11.5196","-0.0001","7.5219"
"","133.2000","8.4510","11.5197","-0.0001","7.5463"
"","133.5000","8.4698","11.5234","-0.0002","7.5779"
"","133.8000","8.4890","11.5298","-0.0001","7.6047"
"","134.1000","8.5077","11.5310","-0.0001","7.6293"
"","134.4000","8.5274","11.5418","-0.0002","7.6549"
"","134.7000","8.5462","11.5432","0.0000","7.6795"
"","135.0000","8.5647","11.5442","-0.0001","7.7041"
"","135.3000","8.5843","11.5535","-0.0002","7.7367"
"","135.6000","8.6034","11.5574","-0.0001","7.7618"
"","135.9000","8.6224","11.5622","-0.0001","7.7869"
"","136.2000","8.6414","11.5654","-0.0001","7.8117"
"","136.5000","8.6601","11.5678","-0.0001","7.8361"
"","136.8000","8.6795","11.5763","-0.0001","7.8610"
"","137.1000","8.6989","11.5820","-0.0001","7.8860"
"","137.4000","8.7175","11.5829","-0.0001","7.9104"
"","137.7000","8.7365","11.5859","-0.0001","7.9353"
"","138.0000","8.7556","11.5926","-0.0001","7.9601"
"","138.3000","8.7748","11.5979","-0.0001","7.9852"
"","138.6000","8.7938","11.6000","-0.0001","8.0100"
"","138.9000","8.8126","11.6040","-0.0001","8.0345"
"","139.2000","8.8319","11.6086","-0.0002","8.0598"
"","139.5000","8.8510","11.6156","-0.0001","8.0845"
"","139.8000","8.8701","11.6193","-0.0001","8.1095"
"","140.1000","8.8887","11.6181","-0.0002","8.1344"
"","140.4000","8.9080","11.6260","-0.0001","8.1591"
"","140.7000","8.9274","11.6321","-0.0001","8.1842"
"","141.0000","8.9460","11.6333","-0.0002","8.2091"
"","141.3000","8.9654","11.6406","-0.0001","8.2342"
"","141.6000","8.9839","11.6380","-0.0001","8.2588"
"","141.9000","9.0032","11.6469","-0.0001","8.2838"
"","142.2000","9.0229","11.6550","-0.0001","8.3090"
"","142.5000","9.0411","11.6529","-0.0001","8.3338"
"","142.8000","9.0605","11.6592","-0.0001","8.3589"
"","143.1000","9.0793","11.6609","-0.0001","8.3839"
"","143.4000","9.0984","11.6668","-0.0001","8.4086"
"","143.7000","9.1182","11.6764","-0.0001","8.4345"
"","144.0000","9.1362","11.6706","-0.0001","8.4587"
"","144.3000","9.1556","11.6784","-0.0001","8.4839"
"","144.6000","9.1751","11.6858","-0.0001","8.5092"
"","144.9000","9.1938","11.6869","-0.0001","8.5341"
"","145.2000","9.2132","11.6935","-0.0001","8.5595"
"","145.5000","9.2316","11.6913","-0.0001","8.5842"
"","145.8000","9.2508","11.6972","-0.0001","8.6094"
"","146.1000","9.2704","11.7056","-0.0001","8.6354"
"","146.4000","9.2890","11.7063","-0.0001","8.6609"
"","146.7000","9.3082","11.7110","-0.0002","8.6863"
"","147.0000","9.3270","11.7118","-0.0002","8.7116"
"","147.3000","9.3463","11.7191","-0.0001","8.7396"
"","147.6000","9.3655","11.7232","-0.0001","8.7671"
"","147.9000","9.3842","11.7250","-0.0001","8.7939"
"","148.2000","9.4033","11.7279","-0.0001","8.8198"
"","148.5000","9.4222","11.7300","-0.0001","8.8451"
"","148.8000","9.4417","11.7402","-0.0001","8.8710"
"","149.1000","9.4605","11.7394","-0.0001","8.8968"
"","149.4000","9.4793","11.7417","-0.0001","8.9221"
"","149.7000","9.4990","11.7506","-0.0002","8.9477"
"","150.0000","9.5176","11.7486","-0.0001","8.9729"
"","150.3000","9.5367","11.7549","-0.0001","8.9983"
"","150.6000","9.5557","11.7571","-0.0001","9.0246"
"","150.9000","9.5746","11.7596","-0.0001","9.0497"
"","151.2000","9.5944","11.7700","0.0000","9.0781"
"","151.5000","9.6129","11.7674","-0.0001","9.1039"
"","151.8000","9.6317","11.7706","-0.0002","9.1289"
"","152.1000","9.6512","11.7768","-0.0001","9.1546"
"","152.4000","9.6698","11.7769","-0.0001","9.1797"
"","152.7000","9.6895","11.7870","-0.0001","9.2056"
"","153.0000","9.7081","11.7845","-0.0001","9.2307"
"","153.3000","9.7268","11.7859","0.0000","9.2558"
"","153.6000","9.7467","11.7966","-0.0001","9.2819"
"","153.9000","9.7653","11.7962","-0.0001","9.3071"
"","154.2000","9.7846","11.8017","-0.0002","9.3326"
"","154.5000","9.8034","11.8025","-0.0002","9.3583"
"","154.8000","9.8220","11.8032","-0.0002","9.3832"
"","155.1000","9.8418","11.8131","-0.0001","9.4092"
"","155.4000","9.8607","11.8146","-0.0001","9.4346"
"","155.7000","9.8796","11.8163","-0.0001","9.4599"
"","156.0000","9.8986","11.8178","-0.0001","9.4855"
"","156.3000","9.9176","11.8224","-0.0002","9.5110"
"","156.6000","9.9370","11.8292","-0.0002","9.5372"
"","156.9000","9.9558","11.8291","-0.0001","9.5625"
"","157.2000","9.9748","11.8323","-0.0002","9.5880"
"","157.5000","9.9939","11.8346","-0.0002","9.6139"
"","157.8000","10.0132","11.8419","-0.0001","9.6395"
"","158.1000","10.0322","11.8438","-0.0001","9.6654"
"","158.4000","10.0508","11.8426","-0.0001","9.6908"
"","158.7000","10.0701","11.8490","-0.0001","9.7165"
"","159.0000","10.0894","11.8533","-0.0001","9.7427"
"","159.3000","10.1082","11.8550","-0.0002","9.7681"
"","159.6000","10.1274","11.8591","-0.0002","9.7939"
"","159.9000","10.1460","11.8573","-0.0001","9.8197"
"","160.2000","10.1654","11.8654","-0.0001","9.8456"
"","160.5000","10.1849","11.8707","-0.0002","9.8719"
"","160.8000","10.2030","11.8660","-0.0001","9.8970"
"","161.1000","10.2224","11.8732","-0.0002","9.9232"
"","161.4000","10.2415","11.8748","-0.0001","9.9489"
"","161.7000","10.2605","11.8794","-0.0001","9.9751"
"","162.0000","10.2801","11.8863","-0.0001","10.0017"
"","162.3000","10.2983","11.8809","-0.0002","10.0271"
"","162.6000","10.3178","11.8882","-0.0001","10.0543"
"","162.9000","10.3372","11.8940","-0.0001","10.0831"
"","163.2000","10.3558","11.8931","-0.0002","10.1125"
"","163.5000","10.3751","11.8982","-0.0002","10.1393"
"","163.8000","10.3937","11.8967","-0.0001","10.1653"
"","164.1000","10.4129","11.9028","-0.0002","10.1917"
"","164.4000","10.4326","11.9097","-0.0002","10.2187"
"","164.7000","10.4509","11.9068","-0.0001","10.2445"
"","165.0000","10.4703","11.9117","-0.0002","10.2708"
"","165.3000","10.4892","11.9130","-0.0001","10.2974"
"","165.6000","10.5084","11.9188","-0.0001","10.3240"
"","165.9000","10.5275","11.9210","-0.0001","10.3508"
"","166.2000","10.5461","11.9202","-0.0001","10.3766"
"","166.5000","10.5653","11.9242","-0.0001","10.4030"
"","166.8000","10.5847","11.9288","-0.0001","10.4301"
"","167.1000","10.6037","11.9334","-0.0002","10.4567"
"","167.4000","10.6225","11.9322","-0.0001","10.4829"
"","167.7000","10.6413","11.9337","-0.0001","10.5093"
"","168.0000","10.6610","11.9416","-0.0002","10.5361"
"","168.3000","10.6798","11.9418","-0.0001","10.5623"
"","168.6000","10.6989","11.9457","-0.0001","10.5887"
"","168.9000","10.7178","11.9459","-0.0002","10.6152"
"","169.2000","10.7364","11.9446","-0.0001","10.6413"
"","169.5000","10.7564","11.9563","-0.0001","10.6684"
"","169.8000","10.7750","11.9532","-0.0002","10.6946"
"","170.1000","10.7935","11.9527","-0.0002","10.7205"
"","170.4000","10.8132","11.9609","-0.0001","10.7474"
"","170.7000","10.8318","11.9593","-0.0002","10.7735"
"","171.0000","10.8516","11.9684","-0.0001","10.8004"
"","171.3000","10.8700","11.9640","-0.0002","10.8263"
"","171.6000","10.8888","11.9662","-0.0002","10.8524"
"","171.9000","10.9088","11.9763","-0.0001","10.8796"
"","172.2000","10.9273","11.9731","-0.0001","10.9055"
"","172.5000","10.9465","11.9776","-0.0001","10.9320"
"","172.8000","10.9655","11.9790","-0.0001","10.9587"
"","173.1000","10.9842","11.9798","-0.0001","10.9849"
"","173.4000","11.0040","11.9889","-0.0001","11.0120"
"","173.7000","11.0225","11.9862","-0.0002","11.0379"
"","174.0000","11.0415","11.9886","-0.0001","11.0645"
"","174.3000","11.0610","11.9939","-0.0001","11.0914"
"","174.6000","11.0797","11.9943","-0.0002","11.1176"
"","174.9000","11.0991","11.9988","-0.0001","11.1443"
"","175.2000","11.1178","11.9971","-0.0001","11.1707"
"","175.5000","11.1368","12.0001","-0.0002","11.1971"
"","175.8000","11.1561","12.0037","-0.0001","11.2239"
"","176.1000","11.1752","12.0077","-0.0001","11.2504"
"","176.4000","11.1941","12.0080","-0.0001","11.2772"
"","176.7000","11.2127","12.0059","-0.0002","11.3036"
"","177.0000","11.2322","12.0135","-0.0001","11.3302"
"","177.3000","11.2515","12.0160","-0.0001","11.3571"
"","177.6000","11.2704","12.0185","-0.0002","11.3835"
"","177.9000","11.2894","12.0199","-0.0001","11.4101"
"","178.2000","11.3078","12.0160","-0.0001","11.4364"
"","178.5000","11.3276","12.0262","-0.0002","11.4635"
"","178.8000","11.3468","12.0287","-0.0001","11.4904"
"","179.1000","11.3652","12.0251","-0.0001","11.5165"
"","179.4000","11.3847","12.0313","-0.0002","11.5435"
"","179.7000","11.4033","12.0296","-0.0002","11.5699"
"","180.0000","11.4228","12.0365","-0.0001","11.5965"
"","180.3000","11.4421","12.0390","-0.0001","11.6236"
"","180.6000","11.4603","12.0337","-0.0002","11.6499"
"","180.9000","11.4799","12.0421","-0.0002","11.6774"
"","181.2000","11.4991","12.0448","-0.0002","11.7061"
"","181.5000","11.5178","12.0444","-0.0002","11.7328"
"","181.8000","11.5372","12.0493","-0.0001","11.7602"
"","182.1000","11.5558","12.0464","-0.0001","11.7874"
"","182.4000","11.5749","12.0509","-0.0002","11.8139"
"","182.7000","11.5944","12.0560","-0.0001","11.8408"
"","183.0000","11.6129","12.0542","-0.0001","11.8674"
"","183.3000","11.6322","12.0579","-0.0002","11.8947"
"","183.6000","11.6513","12.0592","-0.0002","11.9218"
"","183.9000","11.6705","12.0631","-0.0001","11.9491"
"","184.2000","11.6894","12.0635","-0.0002","11.9762"
"","184.5000","11.7082","12.0639","-0.0002","12.0032"
"","184.8000","11.7274","12.0664","-0.0001","12.0309"
"","185.1000","11.7468","12.0705","-0.0002","12.0581"
"","185.4000","11.7658","12.0730","-0.0002","12.0851"
"","185.7000","11.7844","12.0704","-0.0001","12.1120"
"","186.0000","11.8034","12.0734","-0.0001","12.1389"
"","186.3000","11.8231","12.0800","-0.0002","12.1664"
"","186.6000","11.8420","12.0796","-0.0002","12.1935"
"","186.9000","11.8607","12.0802","-0.0002","12.2205"
"","187.2000","11.8796","12.0801","-0.0001","12.2475"
"","187.5000","11.8987","12.0820","-0.0001","12.2744"
"","187.8000","11.9184","12.0894","-0.0001","12.3021"
"","188.1000","11.9369","12.0847","-0.0002","12.3290"
"","188.4000","11.9558","12.0871","-0.0001","12.3555"
"","188.7000","11.9754","12.0934","-0.0001","12.3831"
"","189.0000","11.9939","12.0908","-0.0002","12.4101"
"","189.3000","12.0137","12.0995","-0.0002","12.4378"
"","189.6000","12.0321","12.0943","-0.0001","12.4646"
"","189.9000","12.0509","12.0949","-0.0002","12.4915"
"","190.2000","12.0708","12.1038","-0.0002","12.5200"
"","190.5000","12.0893","12.1005","-0.0002","12.5470"
"","190.8000","12.1087","12.1047","-0.0002","12.5742"
"","191.1000","12.1274","12.1033","-0.0002","12.6016"
"","191.4000","12.1462","12.1038","-0.0001","12.6285"
"","191.7000","12.1660","12.1132","-0.0002","12.6563"
"","192.0000","12.1846","12.1094","-0.0002","12.6831"
"","192.3000","12.2036","12.1110","-0.0001","12.7103"
"","192.6000","12.2228","12.1135","-0.0001","12.7377"
"","192.9000","12.2417","12.1145","-0.0002","12.7647"
"","193.2000","12.2611","12.1189","-0.0001","12.7923"
"","193.5000","12.2798","12.1166","-0.0001","12.8194"
"","193.8000","12.2987","12.1171","-0.0002","12.8463"
"","194.1000","12.3182","12.1218","-0.0001","12.8740"
"","194.4000","12.3371","12.1239","-0.0001","12.9012"
"","194.7000","12.3562","12.1245","-0.0002","12.9286"
"","195.0000","12.3750","12.1233","-0.0002","12.9555"
"","195.3000","12.3944","12.1290","-0.0002","12.9832"
"","195.6000","12.4135","12.1304","-0.0002","13.0108"
"","195.9000","12.4324","12.1311","-0.0001","13.0382"
"","196.2000","12.4514","12.1321","-0.0001","13.0658"
"","196.5000","12.4701","12.1299","-0.0002","13.0929"
"","196.8000","12.4898","12.1388","-0.0002","13.1212"
"","197.1000","12.5088","12.1379","-0.0001","13.1490"
"","197.4000","12.5271","12.1331","-0.0002","13.1767"
"","197.7000","12.5466","12.1395","-0.0002","13.2054"
"","198.0000","12.5655","12.1381","-0.0002","13.2332"
"","198.3000","12.5848","12.1437","-0.0001","13.2620"
"","198.6000","12.6041","12.1460","-0.0002","13.2909"
"","198.9000","12.6223","12.1395","-0.0001","13.3187"
"","199.2000","12.6420","12.1473","-0.0001","13.3468"
"","199.5000","12.6612","12.1489","-0.0001","13.3750"
"","199.8000","12.6799","12.1486","-0.0002","13.4024"
"","200.1000","12.6992","12.1516","-0.0001","13.4306"
"","200.4000","12.7177","12.1473","-0.0002","13.4584"
"","200.7000","12.7372","12.1538","-0.0002","13.4865"
"","201.0000","12.7565","12.1559","-0.0001","13.5150"
"","201.3000","12.7751","12.1540","-0.0002","13.5427"
"","201.6000","12.7943","12.1564","-0.0002","13.5710"
"","201.9000","12.8134","12.1578","-0.0002","13.5991"
"","202.2000","12.8325","12.1607","-0.0001","13.6275"
"","202.5000","12.8516","12.1616","-0.0002","13.6560"
"","202.8000","12.8702","12.1600","-0.0001","13.6839"
"","203.1000","12.8894","12.1621","-0.0002","13.7124"
"","203.4000","12.9088","12.1653","-0.0002","13.7413"
"","203.7000","12.9278","12.1668","-0.0001","13.7697"
"","204.0000","12.9466","12.1653","-0.0002","13.7981"
"","204.3000","12.9655","12.1666","-0.0002","13.8267"
"","204.6000","12.9849","12.1700","-0.0001","13.8559"
"","204.9000","13.0039","12.1700","-0.0001","13.8847"
"","205.2000","13.0229","12.1714","-0.0002","13.9134"
"","205.5000","13.0418","12.1705","-0.0002","13.9424"
"","205.8000","13.0608","12.1722","-0.0002","13.9715"
"","206.1000","13.0804","12.1777","-0.0002","14.0018"
"","206.4000","13.0989","12.1725","-0.0002","14.0304"
"","206.7000","13.1180","12.1757","-0.0001","14.0597"
"","207.0000","13.1374","12.1785","-0.0002","14.0891"
"","207.3000","13.1562","12.1776","-0.0002","14.1179"
"","207.6000","13.1755","12.1821","-0.0001","14.1476"
"","207.9000","13.1940","12.1768","-0.0002","14.1766"
"","208.2000","13.2130","12.1788","-0.0002","14.2061"
"","208.5000","13.2331","12.1879","-0.0002","14.2365"
"","208.8000","13.2513","12.1814","-0.0002","14.2656"
"","209.1000","13.2705","12.1847","-0.0002","14.2953"
"","209.4000","13.2895","12.1839","-0.0002","14.3251"
"","209.7000","13.3084","12.1849","-0.0002","14.3545"
"","210.0000","13.3282","12.1916","-0.0002","14.3849"
"","210.3000","13.3466","12.1871","-0.0001","14.4143"
"","210.6000","13.3654","12.1867","-0.0001","14.4437"
"","210.9000","13.3850","12.1912","-0.0002","14.4743"
"","211.2000","13.4038","12.1907","-0.0002","14.5042"
"","211.5000","13.4231","12.1939","-0.0002","14.5353"
"","211.8000","13.4418","12.1917","-0.0002","14.5655"
"","212.1000","13.4606","12.1913","-0.0002","14.5955"
"","212.4000","13.4804","12.1977","-0.0001","14.6263"
"","212.7000","13.4993","12.1973","-0.0002","14.6562"
"","213.0000","13.5180","12.1949","-0.0002","14.6866"
"","213.3000","13.5370","12.1951","-0.0001","14.7168"
"","213.6000","13.5563","12.1998","-0.0002","14.7476"
"","213.9000","13.5758","12.2022","-0.0002","14.7786"
"","214.2000","13.5943","12.2000","-0.0001","14.8090"
"","214.5000","13.6133","12.1999","-0.0002","14.8396"
"","214.8000","13.6322","12.1990","-0.0002","14.8702"
"","215.1000","13.6518","12.2055","-0.0001","14.9013"
"","215.4000","13.6711","12.2072","-0.0001","14.9336"
"","215.7000","13.6892","12.2001","-0.0002","14.9644"
"","216.0000","13.7088","12.2056","-0.0002","14.9958"
"","216.3000","13.7274","12.2025","-0.0002","15.0265"
"","216.6000","13.7469","12.2085","-0.0002","15.0580"
"","216.9000","13.7661","12.2093","-0.0002","15.0893"
"","217.2000","13.7842","12.2020","-0.0002","15.1199"
"","217.5000","13.8042","12.2104","-0.0002","15.1516"
"","217.8000","13.8231","12.2105","-0.0002","15.1829"
"","218.1000","13.8418","12.2085","-0.0001","15.2142"
"","218.4000","13.8612","12.2121","-0.0002","15.2459"
"","218.7000","13.8798","12.2079","-0.0002","15.2772"
"","219.0000","13.8995","12.2152","-0.0002","15.3092"
"","219.3000","13.9183","12.2126","-0.0002","15.3409"
"","219.6000","13.9369","12.2108","-0.0002","15.3722"
"","219.9000","13.9564","12.2156","-0.0002","15.4045"
"","220.2000","13.9755","12.2159","-0.0002","15.4365"
"","220.5000","13.9946","12.2175","-0.0002","15.4682"
"","220.8000","14.0134","12.2159","-0.0002","15.4995"
"","221.1000","14.0321","12.2141","-0.0002","15.5311"
"","221.4000","14.0518","12.2194","-0.0003","15.5631"
"","221.7000","14.0709","12.2199","-0.0001","15.5953"
"","222.0000","14.0898","12.2204","-0.0001","15.6272"
"","222.3000","14.1084","12.2163","-0.0002","15.6590"
"","222.6000","14.1276","12.2183","-0.0002","15.6910"
"","222.9000","14.1472","12.2225","-0.0001","15.7236"
"","223.2000","14.1661","12.2212","-0.0002","15.7554"
"","223.5000","14.1849","12.2210","-0.0002","15.7871"
"","223.8000","14.2037","12.2188","-0.0001","15.8191"
"","224.1000","14.2230","12.2221","-0.0002","15.8513"
"","224.4000","14.2425","12.2260","-0.0002","15.8839"
"","224.7000","14.2608","12.2191","-0.0002","15.9157"
"","225.0000","14.2800","12.2220","-0.0002","15.9479"
"","225.3000","14.2992","12.2234","-0.0002","15.9806"
"","225.6000","14.3182","12.2232","-0.0002","16.0130"
"","225.9000","14.3376","12.2264","-0.0002","16.0455"
"","226.2000","14.3560","12.2188","-0.0002","16.0775"
"","226.5000","14.3752","12.2224","-0.0002","16.1101"
"","226.8000","14.3950","12.2295","-0.0002","16.1435"
"","227.1000","14.4132","12.2209","-0.0003","16.1754"
"","227.4000","14.4327","12.2259","-0.0002","16.2086"
"","227.7000","14.4516","12.2230","-0.0002","16.2413"
"","228.0000","14.4704","12.2235","-0.0002","16.2742"
"","228.3000","14.4903","12.2299","-0.0001","16.3077"
"","228.6000","14.5085","12.2217","-0.0001","16.3403"
"","228.9000","14.5275","12.2228","-0.0002","16.3732"
"","229.2000","14.5471","12.2263","-0.0002","16.4068"
"","229.5000","14.5659","12.2244","-0.0001","16.4398"
"","229.8000","14.5851","12.2251","-0.0002","16.4728"
"","230.1000","14.6039","12.2219","-0.0002","16.5058"
"","230.4000","14.6229","12.2224","-0.0001","16.5388"
"","230.7000","14.6426","12.2266","-0.0002","16.5733"
"","231.0000","14.6612","12.2235","-0.0002","16.6061"
"","231.3000","14.6800","12.2196","-0.0002","16.6398"
"","231.6000","14.6991","12.2191","-0.0002","16.6732"
"","231.9000","14.7184","12.2216","-0.0002","16.7070"
"","232.2000","14.7377","12.2218","-0.0001","16.7412"
"","232.5000","14.7563","12.2179","-0.0002","16.7747"
"","232.8000","14.7753","12.2155","-0.0002","16.8087"
"","233.1000","14.7943","12.2139","-0.0002","16.8430"
"","233.4000","14.8139","12.2176","-0.0002","16.8772"
"","233.7000","14.8329","12.2140","-0.0002","16.9115"
"","234.0000","14.8511","12.2060","-0.0002","16.9453"
"","234.3000","14.8708","12.2097","-0.0001","16.9801"
"","234.6000","14.8895","12.2040","-0.0002","17.0146"
"","234.9000","14.9090","12.2069","-0.0002","17.0491"
"","235.2000","14.9282","12.2041","-0.0001","17.0841"
"","235.5000","14.9464","12.1932","-0.0002","17.1185"
"","235.8000","14.9664","12.1985","-0.0002","17.1543"
"","236.1000","14.9850","12.1849","-0.0002","17.1901"
"","236.4000","15.0038","12.1702","-0.0002","17.2267"
"","236.7000","15.0235","12.1321","-0.0002","17.2685"
"","236.7350","15.0259","7.2307","-0.0002","17.9794"