File: Tensile Testing/Data/Aluminium_Monatonic.csv
1,Time,Displacement,Force,120Ohm SG Adapter A,Strain 2
,(s),(mm),(kN),(%),(%)
,0,0,0.0002,0,-0.0009
,0.2,0.0019,-0.0006,-0.0001,-0.0009
,0.4,0.019,0.0055,0,-0.0005
,0.6,0.0307,0.0069,0,-0.0005
,0.8,0.0433,0.0082,0.0001,-0.0004
,1,0.0564,0.0099,0,-0.0004
,1.2,0.0689,0.0117,-0.0001,-0.0004
,1.4,0.0816,0.0138,0,-0.0007
,1.6,0.0939,0.0173,0.0001,-0.0007
,1.8,0.1073,0.0196,0,-0.001
,2,0.1195,0.0227,0,-0.0013
,2.2,0.1326,0.0231,0,-0.0017
,2.4,0.1447,0.0237,0,-0.0021
,2.6,0.1579,0.025,0.0001,-0.0026
,2.8,0.1705,0.0299,0,-0.0029
,3,0.183,0.0337,0,-0.0036
,3.2,0.196,0.0363,0,-0.0041
,3.4,0.2088,0.0415,0,-0.0039
,3.6,0.2215,0.0511,0,-0.0042
,3.8,0.2339,0.0722,0,-0.0021
,4,0.2466,0.1022,0,0.0004
,4.2,0.2598,0.1329,-0.0001,0.0006
,4.4,0.2717,0.169,0,0.0009
,4.6,0.2848,0.2086,0,0.0019
,4.8,0.2973,0.2447,0.0001,0.0021
,5,0.3106,0.285,0,0.0032
,5.2,0.3226,0.32,0,0.0038
,5.4,0.3356,0.3587,0,0.0045
,5.6,0.3483,0.3948,0,0.0054
,5.8,0.3611,0.4311,0,0.0056
,6,0.3735,0.4638,0,0.0061
,6.2,0.3864,0.4993,0,0.0065
,6.4,0.3991,0.5296,0,0.0069
,6.6,0.4122,0.5643,0,0.0074
,6.8,0.4242,0.5916,0,0.0075
,7,0.4374,0.6256,-0.0001,0.0081
,7.2,0.4497,0.653,0,0.0082
,7.4,0.4628,0.6849,0,0.0087
,7.6,0.4749,0.712,0,0.0086
,7.8,0.4881,0.7434,0,0.0089
,8,0.5008,0.7723,0,0.0095
,8.2,0.5132,0.8015,0,0.0097
,8.4,0.5259,0.8305,0,0.01
,8.6,0.5386,0.8601,0,0.0106
,8.8,0.5518,0.8897,0,0.0109
,9,0.5639,0.9198,0,0.0112
,9.2,0.5769,0.9491,0,0.012
,9.4,0.5895,0.9814,0,0.0125
,9.6,0.6025,1.0114,0,0.0128
,9.8,0.6149,1.0427,0,0.0135
,10,0.6276,1.072,0,0.0141
,10.2,0.6402,1.1027,0,0.0149
,10.4,0.6533,1.1333,0,0.0155
,10.6,0.6654,1.1618,0,0.0162
,10.8,0.6788,1.1949,0,0.017
,11,0.6909,1.2225,-0.0001,0.0176
,11.2,0.7042,1.2566,0,0.0188
,11.4,0.7159,1.2851,0,0.0193
,11.6,0.7296,1.3214,0,0.0201
,11.8,0.7419,1.3519,0,0.021
,12,0.7548,1.3852,0,0.0223
,12.2,0.767,1.4187,0,0.0233
,12.4,0.7802,1.4535,0,0.0242
,12.6,0.793,1.4882,0,0.0252
,12.8,0.8055,1.5226,0,0.0265
,13,0.8182,1.5567,-0.0001,0.0275
,13.2,0.831,1.5943,0,0.0287
,13.4,0.8436,1.6259,0,0.0295
,13.6,0.8564,1.6656,0,0.031
,13.8,0.8687,1.6966,-0.0001,0.0319
,14,0.882,1.7385,-0.0001,0.0333
,14.2,0.8942,1.7697,-0.0001,0.0345
,14.4,0.9072,1.8108,0,0.0361
,14.6,0.9195,1.8454,0,0.0371
,14.8,0.9326,1.8847,0,0.0384
,15,0.9453,1.9206,0,0.0397
,15.2,0.9576,1.9582,-0.0001,0.0408
,15.4,0.9706,1.9966,0,0.0422
,15.6,0.9834,2.0353,0,0.0438
,15.8,0.996,2.0709,-0.0001,0.045
,16,1.0086,2.1116,0,0.0464
,16.2,1.0214,2.1481,0.0001,0.048
,16.4,1.0344,2.1914,0,0.0496
,16.6,1.0466,2.2264,0,0.0508
,16.8,1.0594,2.2704,0,0.0525
,17,1.0722,2.3104,-0.0001,0.0541
,17.2,1.0851,2.3508,0,0.0554
,17.4,1.0975,2.3917,0,0.0573
,17.6,1.1099,2.4311,0,0.0586
,17.8,1.1232,2.4767,-0.0001,0.0607
,18,1.1355,2.5143,0,0.0622
,18.2,1.1486,2.5594,0.0001,0.064
,18.4,1.1606,2.5967,0,0.0656
,18.6,1.1742,2.6428,0,0.0675
,18.8,1.1864,2.6814,0,0.0691
,19,1.1992,2.724,0,0.0708
,19.2,1.2118,2.7655,0,0.0724
,19.4,1.2244,2.8065,0,0.0743
,19.6,1.2372,2.8486,0,0.0761
,19.8,1.25,2.8932,0,0.0783
,20,1.2624,2.9327,0,0.0802
,20.2,1.276,2.9811,0,0.0821
,20.4,1.2877,3.0161,0,0.0836
,20.6,1.301,3.0658,0,0.086
,20.8,1.3131,3.1041,-0.0001,0.0875
,21,1.3266,3.1531,0,0.0899
,21.2,1.3385,3.1919,0,0.0916
,21.4,1.3516,3.2391,0,0.0936
,21.6,1.3641,3.281,0,0.0956
,21.8,1.3773,3.3268,-0.0001,0.0979
,22,1.3896,3.3708,0,0.0999
,22.2,1.4021,3.414,0,0.1019
,22.4,1.4154,3.4607,0,0.1043
,22.6,1.4277,3.5034,-0.0001,0.1061
,22.8,1.4403,3.5454,0,0.1079
,23,1.4532,3.5929,0,0.1101
,23.2,1.466,3.6346,0.0001,0.1121
,23.4,1.4788,3.6819,0,0.1144
,23.6,1.4909,3.7219,-0.0001,0.1161
,23.8,1.5039,3.7692,-0.0001,0.1185
,24,1.5168,3.815,0,0.1208
,24.2,1.5292,3.8578,0,0.1228
,24.4,1.5421,3.9051,0,0.1253
,24.6,1.5547,3.9485,-0.0001,0.1274
,24.8,1.5679,3.997,-0.0001,0.1297
,25,1.5799,4.0378,0,0.1315
,25.2,1.5928,4.0863,0,0.1338
,25.4,1.6056,4.1316,0,0.1359
,25.6,1.6184,4.1776,-0.0001,0.1384
,25.8,1.6309,4.2238,-0.0001,0.1408
,26,1.6436,4.2701,0,0.1431
,26.2,1.6565,4.3177,0,0.1455
,26.4,1.6693,4.3646,0,0.1478
,26.6,1.6816,4.4072,0,0.1499
,26.8,1.6945,4.4584,0,0.1524
,27,1.7071,4.5012,0,0.1547
,27.2,1.7202,4.5531,0,0.1573
,27.4,1.732,4.5926,0,0.1593
,27.6,1.7456,4.6482,-0.0001,0.1621
,27.8,1.7579,4.6898,-0.0001,0.1642
,28,1.7709,4.7414,0,0.1669
,28.2,1.7829,4.7833,0,0.1691
,28.4,1.7963,4.8369,0,0.1717
,28.6,1.8088,4.8826,-0.0001,0.1743
,28.8,1.8214,4.93,0,0.1768
,29,1.8338,4.9773,0,0.1792
,29.2,1.8471,5.0292,0,0.1818
,29.4,1.8596,5.0743,-0.0001,0.1843
,29.6,1.8724,5.1245,-0.0001,0.1869
,29.8,1.8846,5.1699,-0.0001,0.1894
,30,1.8981,5.2247,0,0.1924
,30.2,1.9102,5.2671,0,0.1947
,30.4,1.9231,5.3185,0,0.1977
,30.6,1.9355,5.3662,0,0.2004
,30.8,1.9486,5.4165,0,0.2029
,31,1.9612,5.4645,0,0.2058
,31.2,1.9735,5.5109,0,0.2082
,31.4,1.9868,5.5663,-0.0001,0.2113
,31.6,1.9991,5.6103,-0.0001,0.2139
,31.8,2.0123,5.6633,0,0.2171
,32,2.0241,5.7074,0,0.2195
,32.2,2.0376,5.7621,0,0.2227
,32.4,2.0503,5.8114,0,0.2255
,32.6,2.0628,5.8582,0,0.2284
,32.8,2.0752,5.9075,0,0.2314
,33,2.0882,5.9587,0,0.2342
,33.2,2.1009,6.0078,-0.0001,0.2373
,33.4,2.1134,6.0555,-0.0001,0.2405
,33.6,2.1258,6.1032,-0.0001,0.2435
,33.8,2.1395,6.1599,-0.0001,0.2469
,34,2.1515,6.2023,0,0.2497
,34.2,2.1646,6.257,0,0.253
,34.4,2.1766,6.3009,-0.0001,0.256
,34.6,2.1901,6.3564,-0.0001,0.2596
,34.8,2.2024,6.401,0,0.2626
,35,2.2151,6.4517,0,0.2661
,35.2,2.2277,6.5012,-0.0001,0.2696
,35.4,2.2408,6.5522,0,0.273
,35.6,2.2534,6.5998,-0.0001,0.2761
,35.8,2.2658,6.6479,0,0.2796
,36,2.2786,6.697,0.0001,0.2831
,36.2,2.2916,6.7487,0,0.287
,36.4,2.3039,6.7921,0,0.2901
,36.6,2.3168,6.8453,0,0.294
,36.8,2.3293,6.8907,0,0.2974
,37,2.3427,6.9448,0,0.3014
,37.2,2.3545,6.9846,0,0.3048
,37.4,2.3675,7.038,-0.0001,0.3088
,37.6,2.3802,7.0846,0,0.3127
,37.8,2.3932,7.1346,0,0.3166
,38,2.4056,7.1808,0,0.3205
,38.2,2.4182,7.228,0,0.3244
,38.4,2.4312,7.278,-0.0001,0.3287
,38.6,2.444,7.3245,-0.0001,0.3331
,38.8,2.4563,7.3691,0,0.3369
,39,2.4692,7.4192,0.0001,0.3413
,39.2,2.4818,7.4636,0,0.3458
,39.4,2.4947,7.5122,-0.0001,0.3503
,39.6,2.5069,7.5549,0,0.3545
,39.8,2.52,7.6048,0,0.3594
,40,2.533,7.6511,0,0.3644
,40.2,2.5453,7.6921,0,0.3687
,40.4,2.5579,7.7398,0,0.3738
,40.6,2.5705,7.7824,0,0.3786
,40.8,2.584,7.8328,0,0.3841
,41,2.5955,7.8675,0,0.3888
,41.2,2.6091,7.9204,0,0.3948
,41.4,2.6214,7.9588,0,0.3998
,41.6,2.6347,8.0061,0,0.4057
,41.8,2.6468,8.0436,0,0.4111
,42,2.6596,8.0894,0,0.4173
,42.2,2.6724,8.1303,-0.0001,0.4232
,42.4,2.6852,8.1713,0,0.4297
,42.6,2.6975,8.2088,0,0.4357
,42.8,2.7105,8.2528,0,0.4425
,43,2.7231,8.289,-0.0001,0.4491
,43.2,2.7362,8.3312,0,0.4562
,43.4,2.7481,8.3617,-0.0001,0.4629
,43.6,2.7616,8.4088,0,0.4706
,43.8,2.7738,8.4384,0,0.4781
,44,2.787,8.4782,0,0.4863
,44.2,2.799,8.5087,0,0.494
,44.4,2.8123,8.548,-0.0001,0.5027
,44.6,2.825,8.579,0,0.5116
,44.8,2.8374,8.6084,0,0.5208
,45,2.85,8.6402,0,0.5302
,45.2,2.8632,8.6739,0,0.5404
,45.4,2.8757,8.6979,-0.0001,0.5511
,45.6,2.8882,8.724,0,0.562
,45.8,2.9007,8.7487,0,0.5732
,46,2.914,8.7773,0,0.5853
,46.2,2.9263,8.7936,-0.0001,0.5976
,46.4,2.9391,8.8192,-0.0001,0.6106
,46.6,2.9516,8.8404,0,0.6235
,46.8,2.9646,8.8611,0,0.6374
,47,2.9773,8.8785,-0.0001,0.6515
,47.2,2.9895,8.8949,-0.0001,0.6651
,47.4,3.0028,8.9201,0,0.6796
,47.6,3.0152,8.9313,-0.0001,0.6941
,47.8,3.0282,8.9503,0,0.7091
,48,3.0402,8.9621,0,0.7236
,48.2,3.0536,8.9837,0,0.7393
,48.4,3.0663,8.9969,0,0.7549
,48.6,3.0787,9.0082,-0.0001,0.7741
,48.8,3.0913,9.0254,0,0.7886
,49,3.1043,9.0425,-0.0001,0.804
,49.2,3.1171,9.0531,0,0.8203
,49.4,3.1296,9.0669,-0.0001,0.8359
,49.6,3.142,9.0781,0,0.8508
,49.8,3.1553,9.0971,-0.0001,0.8668
,50,3.1675,9.1017,-0.0001,0.8826
,50.2,3.1806,9.1208,-0.0001,0.8983
,50.4,3.1926,9.1276,0,0.9135
,50.6,3.2062,9.1481,-0.0001,0.9305
,50.8,3.2184,9.1514,-0.0001,0.9461
,51,3.2313,9.1671,-0.0001,0.9622
,51.2,3.2437,9.1778,-0.0001,0.9779
,51.4,3.2569,9.1918,-0.0001,0.9948
,51.6,3.2693,9.1985,0,1.0106
,51.8,3.2818,9.211,-0.0001,1.0265
,52,3.2946,9.2232,-0.0001,1.0427
,52.2,3.3078,9.2368,-0.0001,1.0595
,52.4,3.3199,9.2395,0,1.0756
,52.6,3.3327,9.2551,0,1.0917
,52.8,3.3453,9.2627,-0.0001,1.1079
,53,3.3586,9.2781,0,1.1246
,53.2,3.3704,9.2798,0,1.1404
,53.4,3.3835,9.2964,-0.0001,1.1569
,53.6,3.3963,9.3068,-0.0001,1.1736
,53.8,3.4092,9.3154,0,1.1904
,54,3.4216,9.3226,0,1.2067
,54.2,3.4341,9.3331,-0.0001,1.2224
,54.4,3.4474,9.3481,-0.0001,1.2393
,54.6,3.4596,9.3513,-0.0001,1.2555
,54.8,3.4726,9.3649,-0.0001,1.2722
,55,3.485,9.3739,-0.0001,1.288
,55.2,3.4982,9.385,-0.0001,1.3046
,55.4,3.5108,9.3916,0.0001,1.321
,55.6,3.5231,9.3983,0.0001,1.3367
,55.8,3.536,9.4115,-0.0001,1.3528
,56,3.5488,9.4208,-0.0001,1.3692
,56.2,3.5611,9.4254,0,1.3853
,56.4,3.574,9.4381,0,1.4013
,56.6,3.5866,9.4463,0.0001,1.4174
,56.8,3.6,9.4596,0,1.434
,57,3.6117,9.4586,0,1.4496
,57.2,3.6249,9.4749,0,1.4658
,57.4,3.6377,9.4835,0,1.4819
,57.6,3.6506,9.4927,0,1.4982
,57.8,3.6628,9.4975,0,1.514
,58,3.6756,9.5095,-0.0001,1.5301
,58.2,3.6886,9.5191,-0.0001,1.5464
,58.4,3.7012,9.5256,0,1.5625
,58.6,3.7136,9.5314,0,1.5783
,58.8,3.7265,9.545,-0.0001,1.5942
,59,3.7393,9.5518,-0.0001,1.6107
,59.2,3.7521,9.5607,0,1.6271
,59.4,3.764,9.563,0,1.6426
,59.6,3.7777,9.5819,-0.0001,1.6592
,59.8,3.7899,9.5826,-0.0001,1.6754
,60,3.8029,9.5932,0,1.6915
,60.2,3.8149,9.5967,0,1.7074
,60.4,3.8283,9.6132,0,1.7241
,60.6,3.8409,9.619,-0.0001,1.7403
,60.8,3.8534,9.625,-0.0001,1.7561
,61,3.8661,9.6349,0,1.7719
,61.2,3.8789,9.6434,0.0001,1.7882
,61.4,3.8918,9.6509,0.0001,1.8046
,61.6,3.9042,9.6566,0,1.8207
,61.8,3.9168,9.6653,-0.0001,1.8367
,62,3.9299,9.6773,-0.0001,1.8536
,62.2,3.9424,9.6818,-0.0001,1.8696
,62.4,3.9549,9.6883,0,1.8853
,62.6,3.9676,9.699,-0.0001,1.9015
,62.8,3.9806,9.7075,-0.0001,1.9203
,63,3.9934,9.7146,0,1.9365
,63.2,4.0056,9.7181,0,1.9521
,63.4,4.0187,9.732,0,1.9682
,63.6,4.0312,9.7374,-0.0001,1.9841
,63.8,4.0443,9.7479,-0.0001,2.0003
,64,4.0561,9.7484,-0.0001,2.0154
,64.2,4.0698,9.7651,0,2.0322
,64.4,4.0821,9.7683,0,2.0482
,64.6,4.0949,9.7764,-0.0001,2.0646
,64.8,4.1075,9.7846,-0.0001,2.0806
,65,4.1203,9.7937,-0.0001,2.096
,65.2,4.133,9.7997,0,2.1122
,65.4,4.1456,9.806,-0.0001,2.1277
,65.6,4.1579,9.8113,-0.0001,2.1431
,65.8,4.1713,9.825,-0.0001,2.1592
,66,4.1836,9.8271,0,2.1751
,66.2,4.1965,9.8378,0,2.1907
,66.4,4.2087,9.8411,0,2.2059
,66.6,4.2221,9.8558,-0.0001,2.2222
,66.8,4.2344,9.8559,-0.0002,2.2376
,67,4.2471,9.8665,-0.0001,2.2532
,67.2,4.2598,9.8745,0,2.2689
,67.4,4.2728,9.8832,-0.0001,2.2849
,67.6,4.2855,9.8886,-0.0001,2.3006
,67.8,4.2976,9.8929,-0.0001,2.3157
,68,4.3107,9.9049,0,2.3319
,68.2,4.3236,9.9125,0,2.3481
,68.4,4.3361,9.9161,-0.0001,2.3638
,68.6,4.3486,9.9246,-0.0001,2.3793
,68.8,4.3614,9.9324,-0.0001,2.395
,69,4.3746,9.9431,0,2.4113
,69.2,4.3865,9.9413,0,2.4261
,69.4,4.3994,9.9533,-0.0001,2.4418
,69.6,4.4122,9.961,-0.0001,2.4581
,69.8,4.4251,9.9687,-0.0001,2.4739
,70,4.4377,9.9755,-0.0001,2.4893
,70.2,4.4499,9.9792,-0.0001,2.5048
,70.4,4.4635,9.9944,-0.0001,2.5213
,70.6,4.4758,9.9951,-0.0001,2.537
,70.8,4.4886,10.0043,-0.0001,2.5534
,71,4.501,10.0092,0,2.5688
,71.2,4.5141,10.019,-0.0001,2.5848
,71.4,4.5267,10.0246,-0.0001,2.6005
,71.6,4.539,10.029,-0.0001,2.6164
,71.8,4.5519,10.0395,0,2.632
,72,4.5648,10.0471,-0.0001,2.6478
,72.2,4.5773,10.0502,0,2.6635
,72.4,4.5901,10.0587,-0.0001,2.6793
,72.6,4.6026,10.0649,-0.0001,2.695
,72.8,4.6158,10.0765,-0.0001,2.7112
,73,4.6278,10.0752,-0.0001,2.7264
,73.2,4.6409,10.0888,-0.0001,2.7423
,73.4,4.6533,10.0914,-0.0001,2.7578
,73.6,4.6668,10.1046,0,2.7743
,73.8,4.6787,10.1033,0,2.7894
,74,4.6916,10.1139,0,2.805
,74.2,4.7044,10.1219,-0.0001,2.8208
,74.4,4.7174,10.1299,-0.0002,2.8368
,74.6,4.7297,10.133,-0.0001,2.8524
,74.8,4.7424,10.1413,0,2.8682
,75,4.755,10.146,0,2.8837
,75.2,4.7683,10.156,-0.0001,2.8998
,75.4,4.7801,10.1555,-0.0001,2.9149
,75.6,4.7934,10.1694,-0.0001,2.9308
,75.8,4.8058,10.1719,-0.0001,2.9463
,76,4.8189,10.1821,-0.0001,2.9624
,76.2,4.831,10.1839,0,2.9777
,76.4,4.8442,10.1947,-0.0001,2.9942
,76.6,4.857,10.2019,0,3.0099
,76.8,4.8694,10.205,0,3.0257
,77,4.8822,10.2132,-0.0001,3.0411
,77.2,4.8946,10.2183,-0.0001,3.0568
,77.4,4.908,10.2297,-0.0002,3.073
,77.6,4.9201,10.2308,-0.0001,3.0882
,77.8,4.9331,10.2406,0,3.104
,78,4.9457,10.2463,-0.0001,3.1196
,78.2,4.9585,10.252,-0.0001,3.1356
,78.4,4.9709,10.257,-0.0001,3.151
,78.6,4.9836,10.2638,0,3.1667
,78.8,4.9964,10.2712,-0.0001,3.1822
,79,5.0093,10.2768,0,3.1982
,79.2,5.0215,10.2797,-0.0001,3.2138
,79.4,5.0348,10.2931,-0.0002,3.2296
,79.6,5.047,10.2948,-0.0001,3.2451
,79.8,5.0604,10.3058,0,3.2616
,80,5.0722,10.3044,-0.0002,3.2763
,80.2,5.0856,10.3193,-0.0001,3.2928
,80.4,5.0981,10.3225,0,3.3081
,80.6,5.111,10.3284,0,3.3239
,80.8,5.1233,10.3324,0,3.3393
,81,5.1362,10.3409,-0.0001,3.3555
,81.2,5.149,10.3469,-0.0001,3.3709
,81.4,5.1615,10.3511,0,3.3865
,81.6,5.174,10.3569,0,3.4024
,81.8,5.1871,10.3673,0,3.4182
,82,5.1997,10.3698,-0.0002,3.4341
,82.2,5.2125,10.3773,-0.0002,3.4502
,82.4,5.2245,10.3783,-0.0002,3.4655
,82.6,5.2381,10.3937,-0.0001,3.4818
,82.8,5.2503,10.393,0,3.4984
,83,5.2633,10.4023,-0.0001,3.5172
,83.2,5.2757,10.4065,-0.0001,3.5323
,83.4,5.2888,10.4159,-0.0001,3.5482
,83.6,5.3015,10.4201,0,3.5641
,83.8,5.3137,10.4226,-0.0001,3.5794
,84,5.3266,10.4316,-0.0001,3.5951
,84.2,5.3396,10.4401,-0.0001,3.6113
,84.4,5.3521,10.4424,-0.0001,3.6271
,84.6,5.3646,10.4481,0,3.6426
,84.8,5.3775,10.456,-0.0001,3.6585
,85,5.3904,10.4627,-0.0002,3.6743
,85.2,5.4026,10.4627,-0.0001,3.6894
,85.4,5.4153,10.4713,0,3.705
,85.6,5.4284,10.4803,-0.0001,3.7209
,85.8,5.4411,10.486,-0.0001,3.7367
,86,5.4538,10.4915,0,3.7524
,86.2,5.4657,10.4909,-0.0001,3.7677
,86.4,5.4795,10.5055,0,3.7841
,86.6,5.4915,10.504,-0.0001,3.7991
,86.8,5.5046,10.5143,-0.0001,3.815
,87,5.5168,10.5164,-0.0001,3.8302
,87.2,5.5303,10.5299,-0.0001,3.8464
,87.4,5.5426,10.5307,0,3.8623
,87.6,5.5552,10.5359,0,3.8782
,87.8,5.5678,10.542,0,3.8936
,88,5.5809,10.5501,-0.0001,3.9097
,88.2,5.5935,10.5533,-0.0001,3.9253
,88.4,5.6058,10.5561,0,3.9407
,88.6,5.6185,10.5643,-0.0001,3.9564
,88.8,5.632,10.5758,-0.0001,3.9727
,89,5.6439,10.5725,-0.0001,3.988
,89.2,5.657,10.5837,-0.0001,4.004
,89.4,5.6693,10.5852,0,4.0191
,89.6,5.6828,10.5977,-0.0001,4.0352
,89.8,5.6947,10.5953,0,4.0507
,90,5.7077,10.6051,-0.0001,4.0667
,90.2,5.7206,10.6123,-0.0001,4.0824
,90.4,5.7333,10.6162,0,4.1009
,90.6,5.7457,10.6193,-0.0001,4.1185
,90.8,5.7581,10.6244,-0.0001,4.1338
,91,5.7714,10.6342,-0.0001,4.1498
,91.2,5.784,10.6377,0,4.1654
,91.4,5.7964,10.6403,0,4.1808
,91.6,5.8092,10.6487,0,4.1967
,91.8,5.822,10.6539,-0.0001,4.2128
,92,5.8349,10.66,-0.0001,4.2285
,92.2,5.8471,10.6604,-0.0001,4.2441
,92.4,5.8601,10.6704,0,4.26
,92.6,5.873,10.6765,-0.0001,4.2758
,92.8,5.8853,10.6782,-0.0001,4.2915
,93,5.8981,10.6861,-0.0001,4.3069
,93.2,5.9106,10.6904,-0.0001,4.3227
,93.4,5.9241,10.7014,0,4.3389
,93.6,5.9361,10.698,-0.0001,4.354
,93.8,5.9489,10.707,-0.0001,4.3701
,94,5.9617,10.7132,-0.0002,4.3857
,94.2,5.9745,10.7179,-0.0001,4.4016
,94.4,5.9869,10.721,-0.0001,4.417
,94.6,5.9996,10.7276,0,4.4327
,94.8,6.0126,10.7349,-0.0001,4.4489
,95,6.0254,10.7397,0,4.465
,95.2,6.0375,10.7396,0,4.4801
,95.4,6.0506,10.7508,-0.0001,4.4959
,95.6,6.0631,10.7529,0,4.5118
,95.8,6.0763,10.7618,-0.0002,4.528
,96,6.0881,10.7591,0,4.5432
,96.2,6.1017,10.7734,0,4.5594
,96.4,6.1141,10.774,0,4.575
,96.6,6.1271,10.7819,-0.0001,4.591
,96.8,6.139,10.7807,-0.0001,4.6061
,97,6.1523,10.7924,0,4.6222
,97.2,6.165,10.7963,-0.0001,4.6381
,97.4,6.1776,10.7998,0,4.6538
,97.6,6.1899,10.8027,-0.0001,4.6695
,97.8,6.2033,10.8131,-0.0001,4.6855
,98,6.2156,10.8135,0,4.7014
,98.2,6.2284,10.8204,0,4.7175
,98.4,6.2406,10.8218,-0.0001,4.7329
,98.6,6.2541,10.8343,0,4.749
,98.8,6.2664,10.8331,-0.0001,4.7643
,99,6.2793,10.8409,-0.0001,4.7805
,99.2,6.2917,10.8433,0,4.796
,99.4,6.3048,10.852,-0.0001,4.812
,99.6,6.3175,10.856,-0.0001,4.8278
,99.8,6.3296,10.8562,0,4.8432
,100,6.3427,10.8663,-0.0001,4.8594
,100.2,6.3554,10.8707,-0.0001,4.8754
,100.4,6.3683,10.8759,0,4.8915
,100.6,6.3804,10.875,-0.0002,4.9067
,100.8,6.3936,10.8852,-0.0001,4.9229
,101,6.4064,10.8907,0,4.9385
,101.2,6.4187,10.8917,-0.0001,4.9539
,101.4,6.4313,10.8968,-0.0001,4.9699
,101.6,6.4444,10.9052,-0.0001,4.9861
,101.8,6.4571,10.9096,-0.0001,5.0025
,102,6.4697,10.9125,0,5.0183
,102.2,6.4819,10.9134,-0.0002,5.0337
,102.4,6.4954,10.9263,-0.0001,5.05
,102.6,6.5077,10.9257,-0.0001,5.0656
,102.8,6.5207,10.9339,0,5.0814
,103,6.5327,10.9332,-0.0001,5.0967
,103.2,6.5463,10.9457,0,5.1133
,103.4,6.5586,10.9451,-0.0001,5.1287
,103.6,6.5712,10.949,-0.0001,5.1447
,103.8,6.5838,10.9537,0,5.1603
,104,6.5969,10.9623,0,5.1763
,104.2,6.6093,10.9632,-0.0001,5.1923
,104.4,6.6219,10.9681,-0.0001,5.2081
,104.6,6.6347,10.9735,-0.0001,5.2239
,104.8,6.6478,10.9818,-0.0001,5.24
,105,6.6599,10.9792,0,5.2557
,105.2,6.6728,10.9876,-0.0001,5.2714
,105.4,6.6853,10.9897,-0.0002,5.2872
,105.6,6.6988,11.0023,-0.0001,5.3035
,105.8,6.7106,10.9977,0,5.319
,106,6.7237,11.0066,0,5.3351
,106.2,6.7365,11.011,-0.0001,5.3511
,106.4,6.7492,11.0149,-0.0001,5.3668
,106.6,6.7618,11.019,0,5.3828
,106.8,6.7742,11.022,0,5.4001
,107,6.7874,11.0314,0,5.4169
,107.2,6.8001,11.034,-0.0001,5.4342
,107.4,6.8123,11.0341,-0.0001,5.4525
,107.6,6.8252,11.0412,0,5.4689
,107.8,6.8382,11.0483,-0.0001,5.485
,108,6.8508,11.05,-0.0001,5.5019
,108.2,6.863,11.0513,0,5.5175
,108.4,6.8761,11.0609,-0.0001,5.5338
,108.6,6.8891,11.0666,-0.0001,5.5502
,108.8,6.9014,11.0667,0,5.566
,109,6.9142,11.0727,-0.0001,5.5819
,109.2,6.9267,11.0749,-0.0001,5.5978
,109.4,6.94,11.0851,-0.0001,5.6145
,109.6,6.9518,11.0805,-0.0001,5.6298
,109.8,6.9653,11.0921,0,5.6467
,110,6.9774,11.0922,0,5.6628
,110.2,6.9909,11.102,-0.0002,5.6797
,110.4,7.0029,11.0993,-0.0002,5.6953
,110.6,7.0157,11.1059,-0.0001,5.712
,110.8,7.0284,11.1106,-0.0001,5.7286
,111,7.0414,11.1161,-0.0001,5.7452
,111.2,7.0536,11.1164,-0.0001,5.7617
,111.4,7.0666,11.1251,-0.0001,5.7785
,111.6,7.0792,11.1268,-0.0001,5.795
,111.8,7.0924,11.1353,-0.0001,5.812
,112,7.1042,11.1303,-0.0001,5.8273
,112.2,7.1176,11.1433,-0.0001,5.8434
,112.4,7.1301,11.144,-0.0001,5.8593
,112.6,7.143,11.1504,-0.0001,5.8754
,112.8,7.1551,11.1498,0,5.8908
,113,7.1683,11.1593,-0.0001,5.9071
,113.2,7.1811,11.1619,-0.0001,5.9231
,113.4,7.1935,11.163,-0.0001,5.9389
,113.6,7.2061,11.1673,-0.0001,5.955
,113.8,7.2191,11.1751,-0.0001,5.9712
,114,7.2318,11.1777,-0.0001,5.987
,114.2,7.2443,11.1807,-0.0001,6.003
,114.4,7.2569,11.1841,-0.0001,6.0187
,114.6,7.27,11.192,-0.0001,6.035
,114.8,7.2824,11.192,-0.0001,6.0509
,115,7.2951,11.1967,-0.0001,6.0666
,115.2,7.3076,11.2002,-0.0001,6.0826
,115.4,7.3208,11.2081,-0.0001,6.0989
,115.6,7.3335,11.211,0,6.1149
,115.8,7.3456,11.2099,0,6.1304
,116,7.3589,11.22,-0.0001,6.1469
,116.2,7.3713,11.2207,-0.0001,6.1624
,116.4,7.3843,11.2267,-0.0001,6.1787
,116.6,7.3964,11.2257,-0.0001,6.1942
,116.8,7.4096,11.2352,-0.0001,6.2105
,117,7.4223,11.2377,-0.0002,6.2265
,117.2,7.4348,11.2394,-0.0001,6.2426
,117.4,7.4472,11.2425,0,6.2584
,117.6,7.4603,11.2501,-0.0001,6.2748
,117.8,7.473,11.2529,-0.0001,6.2908
,118,7.4856,11.2564,-0.0002,6.3068
,118.2,7.498,11.2574,-0.0001,6.3228
,118.4,7.5115,11.2686,-0.0001,6.3393
,118.6,7.5236,11.2652,-0.0001,6.3548
,118.8,7.5367,11.2736,-0.0001,6.3713
,119,7.5487,11.2713,-0.0001,6.3868
,119.2,7.5624,11.2853,-0.0001,6.4035
,119.4,7.5746,11.2822,0,6.4193
,119.6,7.5873,11.2875,-0.0001,6.4354
,119.8,7.5998,11.29,-0.0001,6.4513
,120,7.613,11.297,-0.0002,6.4678
,120.2,7.6253,11.2967,-0.0001,6.4838
,120.4,7.6379,11.3002,0,6.4996
,120.6,7.6508,11.3061,-0.0001,6.5159
,120.8,7.6639,11.3125,-0.0002,6.5324
,121,7.6758,11.3084,-0.0001,6.5481
,121.2,7.6889,11.3177,-0.0001,6.5644
,121.4,7.7013,11.3189,-0.0001,6.5804
,121.6,7.7148,11.3285,-0.0001,6.5972
,121.8,7.7266,11.3237,-0.0001,6.6127
,122,7.7398,11.333,-0.0001,6.6293
,122.2,7.7525,11.3365,0,6.6454
,122.4,7.7653,11.3401,-0.0001,6.6617
,122.6,7.7778,11.3418,-0.0001,6.6778
,122.8,7.7902,11.3443,-0.0001,6.6939
,123,7.8035,11.3524,-0.0002,6.7106
,123.2,7.8157,11.3512,-0.0001,6.7264
,123.4,7.8286,11.3562,-0.0001,6.7427
,123.6,7.8412,11.3599,-0.0001,6.7587
,123.8,7.8542,11.3654,-0.0002,6.7754
,124,7.8667,11.3672,-0.0001,6.7914
,124.2,7.8791,11.3682,-0.0001,6.8076
,124.4,7.892,11.3749,-0.0001,6.8238
,124.6,7.9048,11.379,-0.0001,6.8401
,124.8,7.9174,11.3796,-0.0002,6.8561
,125,7.9301,11.3846,-0.0001,6.8725
,125.2,7.9426,11.3871,-0.0001,6.8885
,125.4,7.9561,11.397,-0.0001,6.9055
,125.6,7.968,11.3922,-0.0001,6.9213
,125.8,7.9812,11.4013,-0.0001,6.9395
,126,7.9937,11.4022,0,6.956
,126.2,8.0067,11.4082,-0.0001,6.9727
,126.4,8.0188,11.406,-0.0001,6.9884
,126.6,8.0317,11.413,-0.0001,7.0047
,126.8,8.0446,11.4177,-0.0001,7.0215
,127,8.0571,11.418,-0.0001,7.0376
,127.2,8.0696,11.4204,-0.0001,7.0536
,127.4,8.0824,11.4263,-0.0001,7.0699
,127.6,8.0953,11.4294,-0.0001,7.0865
,127.8,8.1082,11.4352,-0.0001,7.1029
,128,8.1203,11.4321,-0.0001,7.1188
,128.2,8.1337,11.4435,-0.0001,7.1357
,128.4,8.146,11.4421,-0.0001,7.1516
,128.6,8.1591,11.4487,-0.0002,7.1683
,128.8,8.1711,11.4455,-0.0001,7.1841
,129,8.1843,11.4549,0,7.2009
,129.2,8.1969,11.4561,-0.0001,7.2172
,129.4,8.2097,11.4601,-0.0002,7.2336
,129.6,8.2221,11.462,-0.0001,7.2499
,129.8,8.235,11.4679,-0.0001,7.2663
,130,8.248,11.4717,-0.0001,7.2831
,130.2,8.2602,11.4698,-0.0001,7.2992
,130.4,8.2727,11.4725,-0.0001,7.3154
,130.6,8.2859,11.4806,-0.0001,7.332
,130.8,8.2984,11.4812,0,7.3483
,131,8.3112,11.4855,0,7.3649
,131.2,8.3237,11.4884,-0.0001,7.3815
,131.4,8.3366,11.4913,-0.0001,7.3981
,131.6,8.3495,11.4956,-0.0001,7.4145
,131.8,8.3617,11.4943,0,7.4305
,132,8.375,11.5041,-0.0001,7.4472
,132.2,8.3873,11.5039,-0.0001,7.4636
,132.4,8.4004,11.51,-0.0001,7.4803
,132.6,8.4123,11.5067,-0.0001,7.4963
,132.8,8.4259,11.518,-0.0001,7.5133
,133,8.4382,11.5162,-0.0001,7.5295
,133.2,8.451,11.5197,-0.0001,7.5463
,133.4,8.4632,11.52,-0.0002,7.5626
,133.6,8.4764,11.5275,-0.0002,7.5884
,133.8,8.489,11.5298,-0.0001,7.6047
,134,8.5016,11.5324,-0.0001,7.6205
,134.2,8.5141,11.5334,-0.0001,7.6372
,134.4,8.5274,11.5418,-0.0002,7.6549
,134.6,8.5397,11.5396,-0.0001,7.671
,134.8,8.5526,11.5462,-0.0001,7.6875
,135,8.5647,11.5442,-0.0001,7.7041
,135.2,8.5783,11.5556,-0.0001,7.7246
,135.4,8.5906,11.5535,-0.0001,7.7461
,135.6,8.6034,11.5574,-0.0001,7.7618
,135.8,8.6159,11.5587,-0.0001,7.7775
,136,8.6288,11.564,-0.0001,7.7951
,136.2,8.6414,11.5654,-0.0001,7.8117
,136.4,8.6537,11.566,-0.0001,7.8278
,136.6,8.6667,11.5723,-0.0001,7.8441
,136.8,8.6795,11.5763,-0.0001,7.861
,137,8.6921,11.5764,-0.0001,7.8777
,137.2,8.7046,11.5782,-0.0002,7.8937
,137.4,8.7175,11.5829,-0.0001,7.9104
,137.6,8.7307,11.5896,-0.0001,7.9274
,137.8,8.7427,11.5856,-0.0001,7.9432
,138,8.7556,11.5926,-0.0001,7.9601
,138.2,8.7684,11.5963,-0.0001,7.9767
,138.4,8.7813,11.5996,-0.0002,7.9935
,138.6,8.7938,11.6,-0.0001,8.01
,138.8,8.8062,11.6015,-0.0001,8.0263
,139,8.8195,11.6105,-0.0001,8.0433
,139.2,8.8319,11.6086,-0.0002,8.0598
,139.4,8.8447,11.6138,-0.0001,8.0765
,139.6,8.8569,11.613,-0.0001,8.0925
,139.8,8.8701,11.6193,-0.0001,8.1095
,140,8.8828,11.6205,-0.0001,8.1261
,140.2,8.8951,11.621,-0.0001,8.1425
,140.4,8.908,11.626,-0.0001,8.1591
,140.6,8.921,11.6311,-0.0001,8.1762
,140.8,8.9334,11.6304,-0.0001,8.1926
,141,8.946,11.6333,-0.0002,8.2091
,141.2,8.9586,11.6351,-0.0002,8.2256
,141.4,8.9722,11.6451,-0.0001,8.2429
,141.6,8.9839,11.638,-0.0001,8.2588
,141.8,8.9971,11.647,-0.0001,8.2757
,142,9.0094,11.6461,-0.0001,8.2919
,142.2,9.0229,11.655,-0.0001,8.309
,142.4,9.0348,11.6507,-0.0001,8.3254
,142.6,9.0478,11.6573,-0.0001,8.3423
,142.8,9.0605,11.6592,-0.0001,8.3589
,143,9.0734,11.6631,-0.0002,8.3756
,143.2,9.0857,11.6633,-0.0001,8.392
,143.4,9.0984,11.6668,-0.0001,8.4086
,143.6,9.1113,11.6702,-0.0001,8.4255
,143.8,9.1243,11.6747,-0.0001,8.4425
,144,9.1362,11.6706,-0.0001,8.4587
,144.2,9.1495,11.6801,-0.0001,8.4757
,144.4,9.162,11.6792,-0.0001,8.4923
,144.6,9.1751,11.6858,-0.0001,8.5092
,144.8,9.1872,11.6825,-0.0002,8.5256
,145,9.2002,11.6895,-0.0001,8.5423
,145.2,9.2132,11.6935,-0.0001,8.5595
,145.4,9.2255,11.6924,-0.0001,8.576
,145.6,9.2383,11.6956,-0.0001,8.5925
,145.8,9.2508,11.6972,-0.0001,8.6094
,146,9.2639,11.7032,-0.0001,8.6263
,146.2,9.276,11.7005,-0.0001,8.6436
,146.4,9.289,11.7063,-0.0001,8.6609
,146.6,9.3017,11.7097,-0.0001,8.678
,146.8,9.3147,11.7121,-0.0002,8.6951
,147,9.327,11.7118,-0.0002,8.7116
,147.2,9.3397,11.7147,-0.0001,8.7294
,147.4,9.3526,11.7195,-0.0001,8.7496
,147.6,9.3655,11.7232,-0.0001,8.7671
,147.8,9.3777,11.7213,-0.0002,8.7849
,148,9.3909,11.7298,-0.0002,8.8025
,148.2,9.4033,11.7279,-0.0001,8.8198
,148.4,9.4165,11.7342,-0.0001,8.8373
,148.6,9.4281,11.7276,-0.0001,8.8533
,148.8,9.4417,11.7402,-0.0001,8.871
,149,9.4542,11.7393,-0.0001,8.8884
,149.2,9.4669,11.7413,-0.0001,8.9053
,149.4,9.4793,11.7417,-0.0001,8.9221
,149.6,9.4923,11.747,-0.0001,8.9391
,149.8,9.5052,11.7495,-0.0001,8.9562
,150,9.5176,11.7486,-0.0001,8.9729
,150.2,9.5301,11.751,-0.0001,8.9898
,150.4,9.5432,11.7575,-0.0001,9.0073
,150.6,9.5557,11.7571,-0.0001,9.0246
,150.8,9.5685,11.761,-0.0002,9.0416
,151,9.5808,11.7596,-0.0001,9.0584
,151.2,9.5944,11.77,0,9.0781
,151.4,9.6064,11.7649,-0.0001,9.0953
,151.6,9.6194,11.7706,-0.0001,9.1123
,151.8,9.6317,11.7706,-0.0002,9.1289
,152,9.6449,11.7774,-0.0001,9.146
,152.2,9.6574,11.7769,-0.0001,9.1631
,152.4,9.6698,11.7769,-0.0001,9.1797
,152.6,9.6828,11.7828,-0.0001,9.1969
,152.8,9.696,11.7885,-0.0002,9.2141
,153,9.7081,11.7845,-0.0001,9.2307
,153.2,9.7207,11.7867,-0.0001,9.2476
,153.4,9.7335,11.7907,-0.0001,9.2646
,153.6,9.7467,11.7966,-0.0001,9.2819
,153.8,9.7588,11.7925,-0.0001,9.2985
,154,9.7716,11.7973,-0.0001,9.3155
,154.2,9.7846,11.8017,-0.0002,9.3326
,154.4,9.7973,11.8033,-0.0002,9.3496
,154.6,9.8099,11.8044,-0.0002,9.3667
,154.8,9.822,11.8032,-0.0002,9.3832
,155,9.8356,11.8138,0,9.4007
,155.2,9.8477,11.8089,-0.0001,9.4176
,155.4,9.8607,11.8146,-0.0001,9.4346
,155.6,9.8728,11.8118,-0.0001,9.4512
,155.8,9.8863,11.8207,-0.0001,9.469
,156,9.8986,11.8178,-0.0001,9.4855
,156.2,9.9113,11.8209,-0.0002,9.5027
,156.4,9.9239,11.8238,-0.0002,9.5197
,156.6,9.937,11.8292,-0.0002,9.5372
,156.8,9.9494,11.8268,-0.0001,9.554
,157,9.9621,11.8304,-0.0001,9.5711
,157.2,9.9748,11.8323,-0.0002,9.588
,157.4,9.9882,11.8407,-0.0002,9.6058
,157.6,9.9999,11.8325,-0.0001,9.6222
,157.8,10.0132,11.8419,-0.0001,9.6395
,158,10.0255,11.8402,-0.0001,9.6565
,158.2,10.0389,11.8479,-0.0002,9.6742
,158.4,10.0508,11.8426,-0.0001,9.6908
,158.6,10.0637,11.8472,-0.0001,9.708
,158.8,10.0764,11.8499,-0.0001,9.7253
,159,10.0894,11.8533,-0.0001,9.7427
,159.2,10.1018,11.8522,-0.0001,9.7595
,159.4,10.1143,11.8538,-0.0001,9.7766
,159.6,10.1274,11.8591,-0.0002,9.7939
,159.8,10.14,11.8597,-0.0001,9.8114
,160,10.1525,11.8602,-0.0001,9.8285
,160.2,10.1654,11.8654,-0.0001,9.8456
,160.4,10.1782,11.8669,-0.0001,9.8629
,160.6,10.1911,11.8697,-0.0001,9.8803
,160.8,10.203,11.866,-0.0001,9.897
,161,10.2162,11.8734,-0.0001,9.9146
,161.2,10.2291,11.8764,-0.0001,9.9322
,161.4,10.2415,11.8748,-0.0001,9.9489
,161.6,10.2542,11.8784,-0.0001,9.9663
,161.8,10.2669,11.8805,-0.0001,9.9836
,162,10.2801,11.8863,-0.0001,10.0017
,162.2,10.292,11.8806,-0.0002,10.0184
,162.4,10.3052,11.8876,-0.0002,10.0362
,162.6,10.3178,11.8882,-0.0001,10.0543
,162.8,10.3306,11.8902,-0.0001,10.0735
,163,10.3431,11.891,-0.0001,10.0926
,163.2,10.3558,11.8931,-0.0002,10.1125
,163.4,10.3688,11.898,-0.0001,10.1305
,163.6,10.3816,11.8999,-0.0001,10.1482
,163.8,10.3937,11.8967,-0.0001,10.1653
,164,10.4068,11.9038,-0.0002,10.183
,164.2,10.4194,11.9039,-0.0002,10.2007
,164.4,10.4326,11.9097,-0.0002,10.2187
,164.6,10.4442,11.9023,-0.0001,10.2354
,164.8,10.4579,11.914,-0.0001,10.2536
,165,10.4703,11.9117,-0.0002,10.2708
,165.2,10.4831,11.9136,-0.0001,10.2887
,165.4,10.495,11.9105,-0.0001,10.3059
,165.6,10.5084,11.9188,-0.0001,10.324
,165.8,10.5211,11.9203,-0.0001,10.342
,166,10.5336,11.9191,-0.0002,10.3594
,166.2,10.5461,11.9202,-0.0001,10.3766
,166.4,10.5593,11.9267,-0.0001,10.3943
,166.6,10.5719,11.9263,-0.0001,10.4123
,166.8,10.5847,11.9288,-0.0001,10.4301
,167,10.5966,11.9242,-0.0002,10.4472
,167.2,10.6104,11.9364,-0.0001,10.4657
,167.4,10.6225,11.9322,-0.0001,10.4829
,167.6,10.6353,11.9352,-0.0001,10.5008
,167.8,10.6479,11.9368,-0.0001,10.5185
,168,10.661,11.9416,-0.0002,10.5361
,168.2,10.6735,11.941,-0.0001,10.5537
,168.4,10.6857,11.9385,-0.0001,10.5708
,168.6,10.6989,11.9457,-0.0001,10.5887
,168.8,10.7115,11.9462,-0.0002,10.6063
,169,10.7242,11.9472,-0.0002,10.6241
,169.2,10.7364,11.9446,-0.0001,10.6413
,169.4,10.7497,11.9527,-0.0001,10.6594
,169.6,10.7626,11.9548,-0.0001,10.6771
,169.8,10.775,11.9532,-0.0002,10.6946
,170,10.7874,11.9533,-0.0001,10.7116
,170.2,10.8004,11.9593,-0.0001,10.7298
,170.4,10.8132,11.9609,-0.0001,10.7474
,170.6,10.8258,11.9615,-0.0002,10.7649
,170.8,10.8381,11.9599,-0.0002,10.7822
,171,10.8516,11.9684,-0.0001,10.8004
,171.2,10.8639,11.9653,-0.0001,10.8178
,171.4,10.8767,11.9691,-0.0001,10.8353
,171.6,10.8888,11.9662,-0.0002,10.8524
,171.8,10.9024,11.975,-0.0002,10.8707
,172,10.9146,11.9721,-0.0001,10.888
,172.2,10.9273,11.9731,-0.0001,10.9055
,172.4,10.9402,11.9787,-0.0001,10.9232
,172.6,10.953,11.9797,-0.0002,10.9411
,172.8,10.9655,11.979,-0.0001,10.9587
,173,10.978,11.9794,-0.0002,10.976
,173.2,10.9907,11.982,-0.0001,10.9939
,173.4,11.004,11.9889,-0.0001,11.012
,173.6,11.0161,11.9833,-0.0002,11.0289
,173.8,11.029,11.9888,-0.0002,11.0468
,174,11.0415,11.9886,-0.0001,11.0645
,174.2,11.0549,11.9954,-0.0001,11.0827
,174.4,11.0668,11.9884,-0.0001,11.0999
,174.6,11.0797,11.9943,-0.0002,11.1176
,174.8,11.0925,11.996,-0.0002,11.1354
,175,11.1054,11.9989,-0.0001,11.1531
,175.2,11.1178,11.9971,-0.0001,11.1707
,175.4,11.1302,11.9977,-0.0002,11.188
,175.6,11.1434,12.0033,-0.0002,11.2063
,175.8,11.1561,12.0037,-0.0001,11.2239
,176,11.1685,12.0027,-0.0001,11.2414
,176.2,11.1814,12.0071,-0.0002,11.2593
,176.4,11.1941,12.008,-0.0001,11.2772
,176.6,11.2069,12.0104,-0.0002,11.2949
,176.8,11.2191,12.0079,-0.0002,11.3122
,177,11.2322,12.0135,-0.0001,11.3302
,177.2,11.2453,12.0181,-0.0001,11.3483
,177.4,11.2574,12.0135,-0.0002,11.3655
,177.6,11.2704,12.0185,-0.0002,11.3835
,177.8,11.2827,12.0169,-0.0001,11.4011
,178,11.2962,12.0246,-0.0001,11.4197
,178.2,11.3078,12.016,-0.0001,11.4364
,178.4,11.3212,12.0243,-0.0001,11.4545
,178.6,11.3335,12.0231,-0.0002,11.472
,178.8,11.3468,12.0287,-0.0001,11.4904
,179,11.3589,12.0248,-0.0001,11.5077
,179.2,11.3717,12.0278,-0.0002,11.5255
,179.4,11.3847,12.0313,-0.0002,11.5435
,179.6,11.3974,12.032,-0.0001,11.5611
,179.8,11.4097,12.0303,-0.0001,11.5785
,180,11.4228,12.0365,-0.0001,11.5965
,180.2,11.4355,12.0369,-0.0002,11.6146
,180.4,11.4485,12.0404,-0.0002,11.6324
,180.6,11.4603,12.0337,-0.0002,11.6499
,180.8,11.4737,12.0425,-0.0001,11.6683
,181,11.4861,12.0407,-0.0001,11.6874
,181.2,11.4991,12.0448,-0.0002,11.7061
,181.4,11.5113,12.0424,-0.0002,11.7238
,181.6,11.5243,12.0469,-0.0001,11.742
,181.8,11.5372,12.0493,-0.0001,11.7602
,182,11.5495,12.047,-0.0001,11.7781
,182.2,11.5622,12.0484,-0.0002,11.7959
,182.4,11.5749,12.0509,-0.0002,11.8139
,182.6,11.5877,12.0515,-0.0001,11.8319
,182.8,11.6004,12.054,-0.0001,11.8496
,183,11.6129,12.0542,-0.0001,11.8674
,183.2,11.6262,12.0608,-0.0001,11.886
,183.4,11.6386,12.0577,-0.0002,11.9037
,183.6,11.6513,12.0592,-0.0002,11.9218
,183.8,11.6638,12.0597,-0.0001,11.9395
,184,11.6769,12.0637,-0.0001,11.9582
,184.2,11.6894,12.0635,-0.0002,11.9762
,184.4,11.7018,12.0623,-0.0001,11.9943
,184.6,11.715,12.0687,-0.0001,12.0129
,184.8,11.7274,12.0664,-0.0001,12.0309
,185,11.7403,12.0686,-0.0002,12.0492
,185.2,11.7524,12.0653,-0.0002,12.0666
,185.4,11.7658,12.073,-0.0002,12.0851
,185.6,11.7785,12.074,-0.0001,12.1032
,185.8,11.7908,12.0715,-0.0001,12.121
,186,11.8034,12.0734,-0.0001,12.1389
,186.2,11.8165,12.0776,-0.0002,12.1571
,186.4,11.8292,12.0779,-0.0001,12.1753
,186.6,11.842,12.0796,-0.0002,12.1935
,186.8,11.8541,12.0766,-0.0002,12.2109
,187,11.8676,12.0862,-0.0002,12.2298
,187.2,11.8796,12.0801,-0.0001,12.2475
,187.4,11.8929,12.0867,-0.0002,12.266
,187.6,11.9049,12.0816,-0.0001,12.2833
,187.8,11.9184,12.0894,-0.0001,12.3021
,188,11.9304,12.0833,-0.0002,12.3199
,188.2,11.9434,12.087,-0.0002,12.338
,188.4,11.9558,12.0871,-0.0001,12.3555
,188.6,11.9689,12.0917,-0.0001,12.3741
,188.8,11.9815,12.0914,-0.0002,12.3922
,189,11.9939,12.0908,-0.0002,12.4101
,189.2,12.0069,12.0952,-0.0001,12.4281
,189.4,12.0199,12.0981,-0.0001,12.4466
,189.6,12.0321,12.0943,-0.0001,12.4646
,189.8,12.045,12.0984,-0.0001,12.4829
,190,12.0575,12.0979,-0.0002,12.5008
,190.2,12.0708,12.1038,-0.0002,12.52
,190.4,12.0829,12.0988,-0.0001,12.5381
,190.6,12.0957,12.1023,-0.0001,12.5562
,190.8,12.1087,12.1047,-0.0002,12.5742
,191,12.1213,12.1049,-0.0002,12.5924
,191.2,12.1339,12.105,-0.0002,12.6108
,191.4,12.1462,12.1038,-0.0001,12.6285
,191.6,12.1593,12.1089,-0.0002,12.6468
,191.8,12.1719,12.1085,-0.0002,12.6648
,192,12.1846,12.1094,-0.0002,12.6831
,192.2,12.1972,12.1107,-0.0001,12.7011
,192.4,12.2103,12.1146,-0.0001,12.7197
,192.6,12.2228,12.1135,-0.0001,12.7377
,192.8,12.2353,12.1128,-0.0002,12.7556
,193,12.2482,12.1166,-0.0002,12.774
,193.2,12.2611,12.1189,-0.0001,12.7923
,193.4,12.2735,12.1167,-0.0001,12.8102
,193.6,12.2863,12.1192,-0.0001,12.8285
,193.8,12.2987,12.1171,-0.0002,12.8463
,194,12.3121,12.124,-0.0002,12.8651
,194.2,12.3239,12.1169,-0.0001,12.8825
,194.4,12.3371,12.1239,-0.0001,12.9012
,194.6,12.3497,12.1234,-0.0002,12.9192
,194.8,12.3627,12.1267,-0.0002,12.9379
,195,12.375,12.1233,-0.0002,12.9555
,195.2,12.3877,12.1256,-0.0001,12.974
,195.4,12.4006,12.1289,-0.0002,12.9924
,195.6,12.4135,12.1304,-0.0002,13.0108
,195.8,12.4259,12.1285,-0.0001,13.0289
,196,12.4385,12.1304,-0.0002,13.0473
,196.2,12.4514,12.1321,-0.0001,13.0658
,196.4,12.4645,12.1366,-0.0002,13.0844
,196.6,12.4764,12.1304,-0.0002,13.1024
,196.8,12.4898,12.1388,-0.0002,13.1212
,197,12.5021,12.1351,-0.0001,13.1394
,197.2,12.5152,12.1391,-0.0001,13.1582
,197.4,12.5271,12.1331,-0.0002,13.1767
,197.6,12.5404,12.1401,-0.0002,13.196
,197.8,12.553,12.14,-0.0002,13.2145
,198,12.5655,12.1381,-0.0002,13.2332
,198.2,12.5782,12.1402,-0.0001,13.2523
,198.4,12.5909,12.1418,-0.0002,13.2712
,198.6,12.6041,12.146,-0.0002,13.2909
,198.8,12.6164,12.1431,-0.0001,13.3098
,199,12.6291,12.1442,-0.0001,13.3284
,199.2,12.642,12.1473,-0.0001,13.3468
,199.4,12.6546,12.1465,-0.0002,13.3655
,199.6,12.6671,12.1467,-0.0002,13.3839
,199.8,12.6799,12.1486,-0.0002,13.4024
,200,12.6928,12.1511,-0.0001,13.4211
,200.2,12.7058,12.1534,-0.0002,13.4403
,200.4,12.7177,12.1473,-0.0002,13.4584
,200.6,12.7309,12.1539,-0.0002,13.4774
,200.8,12.7432,12.1507,-0.0001,13.4958
,201,12.7565,12.1559,-0.0001,13.515
,201.2,12.7683,12.1498,-0.0002,13.533
,201.4,12.7818,12.1582,-0.0001,13.5522
,201.6,12.7943,12.1564,-0.0002,13.571
,201.8,12.8069,12.1561,-0.0001,13.59
,202,12.8193,12.1554,-0.0001,13.6084
,202.2,12.8325,12.1607,-0.0001,13.6275
,202.4,12.8453,12.1616,-0.0002,13.6465
,202.6,12.8578,12.1608,-0.0002,13.6654
,202.8,12.8702,12.16,-0.0001,13.6839
,203,12.8835,12.1663,-0.0001,13.7034
,203.2,12.8959,12.1628,-0.0002,13.7221
,203.4,12.9088,12.1653,-0.0002,13.7413
,203.6,12.9208,12.1608,-0.0001,13.7599
,203.8,12.9343,12.1687,-0.0001,13.7794
,204,12.9466,12.1653,-0.0002,13.7981
,204.2,12.9594,12.1679,-0.0002,13.8173
,204.4,12.972,12.1678,-0.0002,13.8363
,204.6,12.9849,12.17,-0.0001,13.8559
,204.8,12.9975,12.1691,-0.0001,13.8751
,205,13.0099,12.1672,-0.0001,13.8939
,205.2,13.0229,12.1714,-0.0002,13.9134
,205.4,13.0359,12.1743,-0.0002,13.9328
,205.6,13.0482,12.1709,-0.0001,13.952
,205.8,13.0608,12.1722,-0.0002,13.9715
,206,13.0736,12.1736,-0.0002,13.9918
,206.2,13.0868,12.1783,-0.0002,14.0112
,206.4,13.0989,12.1725,-0.0002,14.0304
,206.6,13.1117,12.1758,-0.0001,14.0499
,206.8,13.1243,12.1759,-0.0002,14.0694
,207,13.1374,12.1785,-0.0002,14.0891
,207.2,13.1498,12.177,-0.0002,14.1084
,207.4,13.1621,12.1749,-0.0002,14.1275
,207.6,13.1755,12.1821,-0.0001,14.1476
,207.8,13.1879,12.1793,-0.0002,14.167
,208,13.2008,12.1814,-0.0002,14.1868
,208.2,13.213,12.1788,-0.0002,14.2061
,208.4,13.2263,12.1844,-0.0002,14.2263
,208.6,13.2389,12.1835,-0.0001,14.2461
,208.8,13.2513,12.1814,-0.0002,14.2656
,209,13.264,12.1835,-0.0002,14.2854
,209.2,13.2772,12.1877,-0.0001,14.3053
,209.4,13.2895,12.1839,-0.0002,14.3251
,209.6,13.3023,12.186,-0.0002,14.3447
,209.8,13.3147,12.1852,-0.0002,14.3645
,210,13.3282,12.1916,-0.0002,14.3849
,210.2,13.34,12.1842,-0.0001,14.4041
,210.4,13.3532,12.1897,-0.0002,14.4244
,210.6,13.3654,12.1867,-0.0001,14.4437
,210.8,13.379,12.1936,-0.0002,14.4647
,211,13.3908,12.1868,-0.0002,14.484
,211.2,13.4038,12.1907,-0.0002,14.5042
,211.4,13.4165,12.1916,-0.0001,14.5251
,211.6,13.4295,12.1942,-0.0001,14.5454
,211.8,13.4418,12.1917,-0.0002,14.5655
,212,13.4546,12.1935,-0.0002,14.5855
,212.2,13.4676,12.1962,-0.0002,14.606
,212.4,13.4804,12.1977,-0.0001,14.6263
,212.6,13.4926,12.1936,-0.0002,14.6461
,212.8,13.5056,12.1976,-0.0002,14.6663
,213,13.518,12.1949,-0.0002,14.6866
,213.2,13.531,12.1984,-0.0001,14.7071
,213.4,13.5432,12.1948,-0.0001,14.727
,213.6,13.5563,12.1998,-0.0002,14.7476
,213.8,13.5693,12.2016,-0.0002,14.7682
,214,13.5815,12.197,-0.0002,14.7886
,214.2,13.5943,12.2,-0.0001,14.809
,214.4,13.6068,12.1987,-0.0001,14.8292
,214.6,13.6201,12.2039,-0.0002,14.8501
,214.8,13.6322,12.199,-0.0002,14.8702
,215,13.6451,12.202,-0.0002,14.8908
,215.2,13.658,12.2041,-0.0001,14.9115
,215.4,13.6711,12.2072,-0.0001,14.9336
,215.6,13.6832,12.2027,-0.0002,14.954
,215.8,13.6959,12.2035,-0.0001,14.9751
,216,13.7088,12.2056,-0.0002,14.9958
,216.2,13.7216,12.2066,-0.0002,15.0164
,216.4,13.7338,12.2035,-0.0001,15.0369
,216.6,13.7469,12.2085,-0.0002,15.058
,216.8,13.7593,12.2058,-0.0002,15.0787
,217,13.7725,12.2101,-0.0002,15.0998
,217.2,13.7842,12.202,-0.0002,15.1199
,217.4,13.7981,12.2126,-0.0002,15.1415
,217.6,13.8101,12.2068,-0.0002,15.1618
,217.8,13.8231,12.2105,-0.0002,15.1829
,218,13.8354,12.2073,-0.0001,15.2037
,218.2,13.8485,12.2118,-0.0002,15.225
,218.4,13.8612,12.2121,-0.0002,15.2459
,218.6,13.8739,12.2118,-0.0002,15.2672
,218.8,13.8862,12.2093,-0.0002,15.2879
,219,13.8995,12.2152,-0.0002,15.3092
,219.2,13.9119,12.2116,-0.0001,15.3303
,219.4,13.9247,12.2145,-0.0002,15.3515
,219.6,13.9369,12.2108,-0.0002,15.3722
,219.8,13.9503,12.2182,-0.0002,15.3941
,220,13.9626,12.2135,-0.0001,15.4152
,220.2,13.9755,12.2159,-0.0002,15.4365
,220.4,13.9877,12.2128,-0.0002,15.4571
,220.6,14.0008,12.2168,-0.0002,15.4785
,220.8,14.0134,12.2159,-0.0002,15.4995
,221,14.0258,12.2139,-0.0001,15.5203
,221.2,14.039,12.2191,-0.0002,15.5421
,221.4,14.0518,12.2194,-0.0003,15.5631
,221.6,14.0644,12.2176,-0.0002,15.5845
,221.8,14.0768,12.2167,-0.0001,15.6056
,222,14.0898,12.2204,-0.0001,15.6272
,222.2,14.1027,12.2214,-0.0002,15.6486
,222.4,14.115,12.2184,-0.0002,15.67
,222.6,14.1276,12.2183,-0.0002,15.691
,222.8,14.1406,12.2214,-0.0001,15.7129
,223,14.1533,12.2198,-0.0002,15.7341
,223.2,14.1661,12.2212,-0.0002,15.7554
,223.4,14.178,12.2161,-0.0002,15.7762
,223.6,14.1916,12.2243,-0.0001,15.7981
,223.8,14.2037,12.2188,-0.0001,15.8191
,224,14.2169,12.2237,-0.0002,15.8409
,224.2,14.229,12.2191,-0.0002,15.8617
,224.4,14.2425,12.226,-0.0002,15.8839
,224.6,14.2547,12.2212,-0.0002,15.9052
,224.8,14.2674,12.2223,-0.0002,15.9266
,225,14.28,12.222,-0.0002,15.9479
,225.2,14.2931,12.2257,-0.0002,15.9699
,225.4,14.3055,12.2225,-0.0002,15.9915
,225.6,14.3182,12.2232,-0.0002,16.013
,225.8,14.3309,12.2236,-0.0002,16.0346
,226,14.3442,12.2282,-0.0002,16.0566
,226.2,14.356,12.2188,-0.0002,16.0775
,226.4,14.3692,12.2252,-0.0002,16.0997
,226.6,14.3814,12.2216,-0.0002,16.1209
,226.8,14.395,12.2295,-0.0002,16.1435
,227,14.407,12.222,-0.0002,16.1646
,227.2,14.4199,12.2247,-0.0002,16.1866
,227.4,14.4327,12.2259,-0.0002,16.2086
,227.6,14.4456,12.2266,-0.0002,16.2308
,227.8,14.4578,12.2228,-0.0002,16.2522
,228,14.4704,12.2235,-0.0002,16.2742
,228.2,14.4836,12.2272,-0.0002,16.2964
,228.4,14.4963,12.2269,-0.0002,16.3186
,228.6,14.5085,12.2217,-0.0001,16.3403
,228.8,14.5216,12.2262,-0.0002,16.3624
,229,14.5342,12.2246,-0.0003,16.3845
,229.2,14.5471,12.2263,-0.0002,16.4068
,229.4,14.5592,12.2215,-0.0002,16.4283
,229.6,14.5726,12.2277,-0.0002,16.4509
,229.8,14.5851,12.2251,-0.0002,16.4728
,230,14.5975,12.2215,-0.0002,16.4949
,230.2,14.6101,12.2217,-0.0002,16.517
,230.4,14.6229,12.2224,-0.0001,16.5388
,230.6,14.6362,12.2268,-0.0002,16.562
,230.8,14.6482,12.22,-0.0002,16.5838
,231,14.6612,12.2235,-0.0002,16.6061
,231.2,14.674,12.2236,-0.0002,16.6286
,231.4,14.6869,12.2234,-0.0002,16.6511
,231.6,14.6991,12.2191,-0.0002,16.6732
,231.8,14.712,12.2208,-0.0002,16.6955
,232,14.7248,12.2211,-0.0002,16.7182
,232.2,14.7377,12.2218,-0.0001,16.7412
,232.4,14.7497,12.2153,-0.0001,16.7629
,232.6,14.763,12.22,-0.0002,16.7861
,232.8,14.7753,12.2155,-0.0002,16.8087
,233,14.7885,12.2185,-0.0002,16.832
,233.2,14.8002,12.2096,-0.0002,16.8537
,233.4,14.8139,12.2176,-0.0002,16.8772
,233.6,14.8262,12.2129,-0.0002,16.9
,233.8,14.8391,12.2123,-0.0002,16.923
,234,14.8511,12.206,-0.0002,16.9453
,234.2,14.8644,12.2107,-0.0002,16.9686
,234.4,14.8773,12.2104,-0.0002,16.9919
,234.6,14.8895,12.204,-0.0002,17.0146
,234.8,14.9023,12.2048,-0.0002,17.0374
,235,14.9153,12.2062,-0.0001,17.0607
,235.2,14.9282,12.2041,-0.0001,17.0841
,235.4,14.9407,12.1999,-0.0002,17.1071
,235.6,14.953,12.1946,-0.0002,17.1302
,235.8,14.9664,12.1985,-0.0002,17.1543
,236,14.9785,12.187,-0.0002,17.178
,236.2,14.9914,12.1824,-0.0002,17.2023
,236.4,15.0038,12.1702,-0.0002,17.2267
,236.6,15.0171,12.1562,-0.0002,17.253
,236.735,15.0259,7.2307,-0.0002,17.9794