File: Tensile Testing/Data/Mystery_Monatonic.csv
1,Time,Displacement,Force,120Ohm SG Adapter A,Strain 2
,(s),(mm),(kN),(%),(%)
"","0.0000","0.0000","0.0006","0.0000","-0.0002"
"","0.6000","0.0314","0.0389","0.0000","0.0024"
"","1.2000","0.0696","0.0511","0.0000","0.0037"
"","1.8000","0.1075","0.0591","0.0001","0.0046"
"","2.4000","0.1453","0.0742","-0.0001","0.0054"
"","3.0000","0.1838","0.0795","0.0000","0.0056"
"","3.6000","0.2222","0.1003","0.0000","0.0059"
"","4.2000","0.2599","0.1343","-0.0001","0.0062"
"","4.8000","0.2978","0.2071","0.0000","0.0068"
"","5.4000","0.3359","0.3011","0.0000","0.0073"
"","6.0000","0.3746","0.4247","-0.0001","0.0093"
"","6.6000","0.4122","0.5610","0.0000","0.0115"
"","7.2000","0.4506","0.7038","0.0000","0.0141"
"","7.8000","0.4882","0.8442","0.0000","0.0169"
"","8.4000","0.5267","0.9936","0.0000","0.0204"
"","9.0000","0.5644","1.1320","0.0001","0.0234"
"","9.6000","0.6029","1.2779","0.0000","0.0270"
"","10.2000","0.6411","1.4145","0.0000","0.0302"
"","10.8000","0.6785","1.5448","0.0001","0.0333"
"","11.4000","0.7172","1.6782","0.0000","0.0365"
"","12.0000","0.7552","1.8052","-0.0001","0.0397"
"","12.6000","0.7938","1.9349","0.0000","0.0432"
"","13.2000","0.8309","2.0580","-0.0001","0.0464"
"","13.8000","0.8695","2.1877","-0.0001","0.0497"
"","14.4000","0.9078","2.3118","0.0000","0.0532"
"","15.0000","0.9461","2.4422","0.0000","0.0571"
"","15.6000","0.9837","2.5658","0.0000","0.0609"
"","16.2000","1.0218","2.7004","0.0000","0.0651"
"","16.8000","1.0599","2.8311","-0.0001","0.0690"
"","17.4000","1.0983","2.9666","-0.0001","0.0735"
"","18.0000","1.1362","3.1002","0.0000","0.0778"
"","18.6000","1.1743","3.2521","0.0000","0.0831"
"","19.2000","1.2124","3.3964","-0.0001","0.0879"
"","19.8000","1.2501","3.5292","-0.0001","0.0923"
"","20.4000","1.2891","3.6768","0.0000","0.0971"
"","21.0000","1.3268","3.8105","0.0000","0.1020"
"","21.6000","1.3648","3.9506","0.0000","0.1076"
"","22.2000","1.4024","4.0820","0.0000","0.1131"
"","22.8000","1.4412","4.2284","-0.0001","0.1194"
"","23.4000","1.4794","4.3679","0.0000","0.1254"
"","24.0000","1.5172","4.5053","0.0000","0.1318"
"","24.6000","1.5552","4.6410","0.0000","0.1387"
"","25.2000","1.5934","4.7837","-0.0001","0.1458"
"","25.8000","1.6316","4.9206","0.0000","0.1535"
"","26.4000","1.6696","5.0596","0.0000","0.1609"
"","27.0000","1.7079","5.2008","-0.0001","0.1692"
"","27.6000","1.7456","5.3356","0.0000","0.1777"
"","28.2000","1.7839","5.4735","-0.0001","0.1867"
"","28.8000","1.8218","5.6051","0.0000","0.1962"
"","29.4000","1.8605","5.7502","0.0000","0.2065"
"","30.0000","1.8980","5.8799","0.0000","0.2170"
"","30.6000","1.9361","6.0141","0.0000","0.2285"
"","31.2000","1.9742","6.1410","0.0000","0.2405"
"","31.8000","2.0128","6.2762","0.0000","0.2539"
"","32.4000","2.0507","6.4016","0.0000","0.2673"
"","33.0000","2.0884","6.5214","0.0000","0.2822"
"","33.6000","2.1268","6.6407","-0.0001","0.2985"
"","34.2000","2.1650","6.7543","-0.0001","0.3162"
"","34.8000","2.2032","6.8640","0.0001","0.3357"
"","35.4000","2.2410","6.9629","0.0000","0.3564"
"","36.0000","2.2794","7.0646","-0.0001","0.3801"
"","36.6000","2.3170","7.1479","0.0000","0.4048"
"","37.2000","2.3556","7.2328","0.0001","0.4330"
"","37.8000","2.3935","7.3050","-0.0001","0.4622"
"","38.4000","2.4319","7.3826","0.0001","0.4941"
"","39.0000","2.4692","7.4349","0.0000","0.5274"
"","39.6000","2.5077","7.4959","0.0000","0.5634"
"","40.2000","2.5461","7.5481","-0.0001","0.6014"
"","40.8000","2.5843","7.5980","0.0000","0.6406"
"","41.4000","2.6219","7.6390","-0.0001","0.6808"
"","42.0000","2.6599","7.6765","0.0000","0.7232"
"","42.6000","2.6987","7.7193","0.0000","0.7674"
"","43.2000","2.7364","7.7471","0.0000","0.8117"
"","43.8000","2.7747","7.7812","0.0000","0.8577"
"","44.4000","2.8122","7.8067","-0.0001","0.9039"
"","45.0000","2.8508","7.8386","0.0000","0.9519"
"","45.6000","2.8886","7.8575","0.0000","1.0000"
"","46.2000","2.9269","7.8826","0.0000","1.0491"
"","46.8000","2.9652","7.9082","0.0000","1.0983"
"","47.4000","3.0029","7.9306","0.0000","1.1474"
"","48.0000","3.0409","7.9430","0.0000","1.1980"
"","48.6000","3.0794","7.9675","0.0000","1.2488"
"","49.2000","3.1177","7.9857","-0.0001","1.3001"
"","49.8000","3.1553","8.0024","0.0000","1.3506"
"","50.4000","3.1934","8.0171","-0.0001","1.4023"
"","51.0000","3.2316","8.0310","-0.0001","1.4544"
"","51.6000","3.2703","8.0542","-0.0001","1.5067"
"","52.2000","3.3077","8.0596","0.0001","1.5583"
"","52.8000","3.3461","8.0811","0.0000","1.6109"
"","53.4000","3.3839","8.0898","0.0000","1.6633"
"","54.0000","3.4225","8.1051","0.0000","1.7166"
"","54.6000","3.4601","8.1120","0.0000","1.7694"
"","55.2000","3.4986","8.1319","0.0000","1.8222"
"","55.8000","3.5364","8.1429","0.0000","1.8751"
"","56.4000","3.5743","8.1499","0.0000","1.9304"
"","57.0000","3.6128","8.1588","-0.0001","1.9840"
"","57.6000","3.6508","8.1740","0.0000","2.0369"
"","58.2000","3.6891","8.1897","-0.0001","2.0901"
"","58.8000","3.7265","8.1912","0.0000","2.1432"
"","59.4000","3.7653","8.2054","0.0000","2.1978"
"","60.0000","3.8034","8.2136","0.0000","2.2515"
"","60.6000","3.8414","8.2275","0.0000","2.3056"
"","61.2000","3.8790","8.2305","0.0000","2.3587"
"","61.8000","3.9176","8.2466","0.0000","2.4134"
"","62.4000","3.9557","8.2508","0.0000","2.4671"
"","63.0000","3.9938","8.2617","0.0000","2.5209"
"","63.6000","4.0318","8.2688","0.0000","2.5746"
"","64.2000","4.0697","8.2786","-0.0001","2.6285"
"","64.8000","4.1080","8.2887","0.0000","2.6827"
"","65.4000","4.1459","8.2900","0.0000","2.7371"
"","66.0000","4.1846","8.3047","0.0000","2.7918"
"","66.6000","4.2221","8.3124","0.0001","2.8445"
"","67.2000","4.2602","8.3203","0.0000","2.8978"
"","67.8000","4.2981","8.3207","-0.0001","2.9509"
"","68.4000","4.3371","8.3375","-0.0001","3.0046"
"","69.0000","4.3750","8.3432","0.0000","3.0579"
"","69.6000","4.4126","8.3511","0.0000","3.1110"
"","70.2000","4.4506","8.3540","-0.0001","3.1675"
"","70.8000","4.4892","8.3646","0.0000","3.2232"
"","71.4000","4.5274","8.3729","-0.0001","3.2801"
"","72.0000","4.5651","8.3806","-0.0001","3.3362"
"","72.6000","4.6034","8.3896","0.0000","3.3927"
"","73.2000","4.6412","8.3906","0.0000","3.4430"
"","73.8000","4.6797","8.3985","0.0000","3.4929"
"","74.4000","4.7175","8.4054","0.0000","3.5351"
"","75.0000","4.7562","8.4265","0.0000","3.5770"
"","75.6000","4.7933","8.4237","0.0000","3.6205"
"","76.2000","4.8319","8.4379","0.0000","3.6743"
"","76.8000","4.8700","8.4356","0.0000","3.7330"
"","77.4000","4.9085","8.4605","-0.0001","3.7945"
"","78.0000","4.9460","8.4742","0.0000","3.8481"
"","78.6000","4.9840","8.4647","0.0000","3.8964"
"","79.2000","5.0226","8.4723","-0.0001","3.9496"
"","79.8000","5.0609","8.4667","0.0000","4.0090"
"","80.4000","5.0987","8.4771","-0.0001","4.0759"
"","81.0000","5.1363","8.4836","0.0000","4.1396"
"","81.6000","5.1750","8.4964","0.0000","4.2008"
"","82.2000","5.2129","8.5003","0.0000","4.2575"
"","82.8000","5.2513","8.5149","-0.0001","4.3143"
"","83.4000","5.2890","8.5228","-0.0001","4.3650"
"","84.0000","5.3272","8.5367","0.0000","4.3961"
"","84.6000","5.3651","8.5438","-0.0001","4.4044"
"","85.2000","5.4036","8.5738","0.0000","4.4087"
"","85.8000","5.4417","8.5711","0.0000","4.4211"
"","86.4000","5.4795","8.5568","-0.0001","4.4684"
"","87.0000","5.5172","8.5532","0.0000","4.5213"
"","87.6000","5.5557","8.5644","-0.0001","4.5842"
"","88.2000","5.5944","8.5809","-0.0001","4.6494"
"","88.8000","5.6319","8.5852","0.0000","4.7133"
"","89.4000","5.6700","8.5887","0.0000","4.7794"
"","90.0000","5.7079","8.5878","0.0000","4.8474"
"","90.6000","5.7467","8.5817","-0.0001","4.9210"
"","91.2000","5.7842","8.5839","0.0001","4.9932"
"","91.8000","5.8227","8.5991","0.0000","5.0652"
"","92.4000","5.8605","8.6041","0.0000","5.1373"
"","93.0000","5.8985","8.6122","0.0000","5.2104"
"","93.6000","5.9367","8.6122","0.0000","5.2836"
"","94.2000","5.9751","8.6248","-0.0001","5.3560"
"","94.8000","6.0132","8.6378","-0.0001","5.4279"
"","95.4000","6.0508","8.6464","0.0000","5.4983"
"","96.0000","6.0891","8.6573","0.0000","5.5702"
"","96.6000","6.1275","8.6642","0.0000","5.6377"
"","97.2000","6.1658","8.6809","0.0000","5.6765"
"","97.8000","6.2031","8.6796","-0.0001","5.7014"
"","98.4000","6.2417","8.6940","0.0000","5.7083"
"","99.0000","6.2795","8.7151","0.0000","5.7103"
"","99.6000","6.3182","8.7570","-0.0001","5.7142"
"","100.2000","6.3557","8.6702","0.0000","5.7199"
"","100.8000","6.3940","8.6801","0.0000","5.7290"
"","101.4000","6.4322","8.6794","-0.0001","5.7489"
"","102.0000","6.4700","8.6944","-0.0001","5.7865"
"","102.6000","6.5084","8.6982","0.0000","5.8365"
"","103.2000","6.5464","8.7088","-0.0001","5.8986"
"","103.8000","6.5844","8.7173","-0.0001","5.9676"
"","104.4000","6.6223","8.7190","0.0000","6.0381"
"","105.0000","6.6610","8.7314","0.0000","6.1105"
"","105.6000","6.6990","8.7277","-0.0001","6.1835"
"","106.2000","6.7368","8.7318","0.0000","6.2556"
"","106.8000","6.7744","8.7223","0.0000","6.3292"
"","107.4000","6.8134","8.7344","0.0000","6.4031"
"","108.0000","6.8514","8.7381","0.0000","6.4765"
"","108.6000","6.8891","8.7438","0.0000","6.5489"
"","109.2000","6.9271","8.7493","0.0000","6.6220"
"","109.8000","6.9655","8.7590","-0.0001","6.6941"
"","110.4000","7.0038","8.7635","0.0000","6.7674"
"","111.0000","7.0415","8.7661","0.0000","6.8394"
"","111.6000","7.0801","8.7796","0.0000","6.9129"
"","112.2000","7.1175","8.7867","0.0000","6.9838"
"","112.8000","7.1560","8.7994","0.0000","7.0565"
"","113.4000","7.1941","8.8010","0.0000","7.1291"
"","114.0000","7.2326","8.8155","0.0000","7.2025"
"","114.6000","7.2702","8.8185","-0.0001","7.2681"
"","115.2000","7.3081","8.8253","0.0000","7.3065"
"","115.8000","7.3464","8.8301","0.0001","7.3291"
"","116.4000","7.3851","8.8526","0.0000","7.3420"
"","117.0000","7.4227","8.8606","-0.0001","7.3450"
"","117.6000","7.4605","8.8836","-0.0001","7.3470"
"","118.2000","7.4990","8.9299","-0.0001","7.3502"
"","118.8000","7.5370","8.8210","-0.0001","7.3466"
"","119.4000","7.5752","8.8334","0.0000","7.3473"
"","120.0000","7.6129","8.8271","0.0000","7.3503"
"","120.6000","7.6515","8.8449","0.0000","7.3808"
"","121.2000","7.6891","8.8438","0.0001","7.4178"
"","121.8000","7.7277","8.8510","0.0000","7.4521"
"","122.4000","7.7655","8.8539","-0.0001","7.5027"
"","123.0000","7.8039","8.8690","0.0000","7.5699"
"","123.6000","7.8414","8.8687","0.0000","7.6413"
"","124.2000","7.8799","8.8756","-0.0001","7.7141"
"","124.8000","7.9183","8.8780","-0.0001","7.7875"
"","125.4000","7.9560","8.8789","0.0000","7.8616"
"","126.0000","7.9940","8.8772","-0.0001","7.9353"
"","126.6000","8.0320","8.8766","-0.0001","8.0086"
"","127.2000","8.0708","8.8848","0.0001","8.0827"
"","127.8000","8.1084","8.8847","-0.0001","8.1551"
"","128.4000","8.1467","8.8952","-0.0001","8.2275"
"","129.0000","8.1845","8.9001","0.0000","8.3002"
"","129.6000","8.2230","8.9101","0.0000","8.3736"
"","130.2000","8.2613","8.9105","0.0000","8.4476"
"","130.8000","8.2991","8.9175","-0.0001","8.5197"
"","131.4000","8.3372","8.9247","-0.0001","8.5925"
"","132.0000","8.3749","8.9323","0.0000","8.6641"
"","132.6000","8.4132","8.9371","0.0000","8.7372"
"","133.2000","8.4516","8.9488","-0.0001","8.8096"
"","133.8000","8.4900","8.9599","-0.0001","8.8819"
"","134.4000","8.5272","8.9592","-0.0001","8.9528"
"","135.0000","8.5657","8.9672","0.0000","9.0261"
"","135.6000","8.6036","8.9701","-0.0001","9.0968"
"","136.2000","8.6425","8.9836","-0.0001","9.1477"
"","136.8000","8.6799","8.9850","0.0000","9.1797"
"","137.4000","8.7180","8.9994","0.0000","9.1974"
"","138.0000","8.7563","9.0089","-0.0001","9.2057"
"","138.6000","8.7943","9.0158","0.0000","9.2079"
"","139.2000","8.8325","9.0021","0.0000","9.2079"
"","139.8000","8.8706","9.0001","-0.0001","9.2086"
"","140.4000","8.9085","8.9881","0.0000","9.2080"
"","141.0000","8.9463","8.9861","-0.0001","9.2111"
"","141.6000","8.9851","8.9944","-0.0001","9.2315"
"","142.2000","9.0231","9.0004","0.0000","9.2644"
"","142.8000","9.0612","9.0090","-0.0001","9.2983"
"","143.4000","9.0985","9.0046","-0.0001","9.3337"
"","144.0000","9.1374","9.0164","0.0000","9.3909"
"","144.6000","9.1754","9.0213","-0.0001","9.4596"
"","145.2000","9.2136","9.0262","0.0000","9.5310"
"","145.8000","9.2512","9.0236","-0.0001","9.6027"
"","146.4000","9.2896","9.0305","0.0000","9.6750"
"","147.0000","9.3279","9.0261","-0.0001","9.7481"
"","147.6000","9.3658","9.0265","0.0000","9.8198"
"","148.2000","9.4040","9.0274","0.0000","9.8934"
"","148.8000","9.4417","9.0349","-0.0001","9.9651"
"","149.4000","9.4800","9.0397","0.0000","10.0382"
"","150.0000","9.5182","9.0389","0.0000","10.1120"
"","150.6000","9.5567","9.0505","0.0000","10.1859"
"","151.2000","9.5942","9.0539","0.0000","10.2573"
"","151.8000","9.6324","9.0584","0.0001","10.3297"
"","152.4000","9.6703","9.0596","0.0000","10.4016"
"","153.0000","9.7092","9.0744","0.0000","10.4740"
"","153.6000","9.7469","9.0766","-0.0001","10.5431"
"","154.2000","9.7846","9.0808","-0.0001","10.6083"
"","154.8000","9.8228","9.0824","0.0000","10.6591"
"","155.4000","9.8613","9.0843","0.0000","10.6973"
"","156.0000","9.8995","9.0946","-0.0001","10.7345"
"","156.6000","9.9371","9.0967","-0.0001","10.7918"
"","157.2000","9.9755","9.1109","0.0000","10.8561"
"","157.8000","10.0132","9.1115","0.0000","10.9221"
"","158.4000","10.0518","9.1176","-0.0001","10.9910"
"","159.0000","10.0897","9.1192","-0.0001","11.0597"
"","159.6000","10.1280","9.1313","-0.0001","11.1276"
"","160.2000","10.1654","9.1211","-0.0001","11.1850"
"","160.8000","10.2038","9.1227","-0.0001","11.2221"
"","161.4000","10.2422","9.0988","-0.0001","11.2332"
"","162.0000","10.2806","9.1458","-0.0002","11.2376"
"","162.6000","10.3181","9.1814","-0.0001","11.2418"
"","163.2000","10.3561","9.1959","0.0000","11.2482"
"","163.8000","10.3947","9.2124","0.0000","11.2590"
"","164.4000","10.4327","9.2247","0.0000","11.2816"
"","165.0000","10.4708","9.2395","0.0000","11.3168"
"","165.6000","10.5085","9.1906","-0.0002","11.3588"
"","166.2000","10.5472","9.1693","0.0000","11.3596"
"","166.8000","10.5848","9.1590","0.0000","11.3593"
"","167.4000","10.6232","9.1445","0.0000","11.3598"
"","168.0000","10.6612","9.1516","0.0000","11.3624"
"","168.6000","10.6993","9.1589","0.0001","11.3710"
"","169.2000","10.7372","9.1529","0.0001","11.3995"
"","169.8000","10.7756","9.1596","-0.0001","11.4341"
"","170.4000","10.8139","9.1656","0.0000","11.4789"
"","171.0000","10.8514","9.1711","0.0000","11.5368"
"","171.6000","10.8896","9.1710","-0.0001","11.6058"
"","172.2000","10.9279","9.1731","0.0000","11.6784"
"","172.8000","10.9664","9.1805","0.0000","11.7548"
"","173.4000","11.0039","9.1719","-0.0001","11.8269"
"","174.0000","11.0421","9.1790","0.0000","11.9007"
"","174.6000","11.0801","9.1757","0.0000","11.9744"
"","175.2000","11.1190","9.1845","0.0001","12.0489"
"","175.8000","11.1564","9.1779","-0.0001","12.1221"
"","176.4000","11.1948","9.1884","-0.0001","12.1961"
"","177.0000","11.2325","9.1926","0.0001","12.2686"
"","177.6000","11.2706","9.1964","0.0000","12.3424"
"","178.2000","11.3090","9.1980","-0.0001","12.4168"
"","178.8000","11.3471","9.2049","0.0000","12.4898"
"","179.4000","11.3854","9.2125","-0.0001","12.5633"
"","180.0000","11.4226","9.2086","-0.0001","12.6358"
"","180.6000","11.4614","9.2160","0.0000","12.7106"
"","181.2000","11.4995","9.2216","0.0000","12.7838"
"","181.8000","11.5379","9.2284","-0.0001","12.8580"
"","182.4000","11.5752","9.2221","-0.0001","12.9313"
"","183.0000","11.6137","9.2392","-0.0001","13.0038"
"","183.6000","11.6519","9.2452","-0.0001","13.0777"
"","184.2000","11.6901","9.2527","0.0000","13.1509"
"","184.8000","11.7281","9.2536","0.0001","13.2244"
"","185.4000","11.7661","9.2631","-0.0001","13.2971"
"","186.0000","11.8043","9.2725","-0.0001","13.3708"
"","186.6000","11.8423","9.2861","0.0000","13.4407"
"","187.2000","11.8806","9.3224","-0.0001","13.5076"
"","187.8000","11.9185","9.3485","-0.0001","13.5765"
"","188.4000","11.9565","9.3599","-0.0001","13.6438"
"","189.0000","11.9943","9.3339","-0.0001","13.6839"
"","189.6000","12.0333","9.3338","-0.0001","13.6948"
"","190.2000","12.0709","9.3329","-0.0002","13.7031"
"","190.8000","12.1089","9.3265","-0.0001","13.7157"
"","191.4000","12.1468","9.3244","-0.0001","13.7191"
"","192.0000","12.1855","9.3089","-0.0001","13.7203"
"","192.6000","12.2236","9.3150","0.0000","13.7204"
"","193.2000","12.2611","9.3196","-0.0001","13.7211"
"","193.8000","12.2994","9.3182","0.0001","13.7212"
"","194.4000","12.3376","9.3132","-0.0002","13.7217"
"","195.0000","12.3759","9.3094","0.0000","13.7215"
"","195.6000","12.4137","9.3012","0.0001","13.7209"
"","196.2000","12.4521","9.3117","0.0000","13.7327"
"","196.8000","12.4896","9.3071","0.0000","13.7602"
"","197.4000","12.5282","9.3141","-0.0001","13.7867"
"","198.0000","12.5662","9.3104","0.0000","13.8277"
"","198.6000","12.6048","9.3208","-0.0001","13.8919"
"","199.2000","12.6420","9.3167","-0.0001","13.9630"
"","199.8000","12.6801","9.3172","-0.0001","14.0365"
"","200.4000","12.7186","9.3163","-0.0001","14.1111"
"","201.0000","12.7570","9.3228","0.0000","14.1841"
"","201.6000","12.7948","9.3187","-0.0001","14.2578"
"","202.2000","12.8324","9.3185","-0.0001","14.3301"
"","202.8000","12.8712","9.3273","0.0000","14.4043"
"","203.4000","12.9091","9.3260","0.0000","14.4781"
"","204.0000","12.9473","9.3304","-0.0001","14.5520"
"","204.6000","12.9854","9.3342","-0.0001","14.6257"
"","205.2000","13.0235","9.3434","0.0000","14.6987"
"","205.8000","13.0612","9.3375","0.0001","14.7727"
"","206.4000","13.0997","9.3447","-0.0001","14.8469"
"","207.0000","13.1379","9.3475","-0.0001","14.9205"
"","207.6000","13.1760","9.3564","0.0001","14.9934"
"","208.2000","13.2135","9.3525","-0.0001","15.0667"
"","208.8000","13.2518","9.3563","-0.0001","15.1407"
"","209.4000","13.2905","9.3631","-0.0001","15.2151"
"","210.0000","13.3281","9.3660","-0.0001","15.2875"
"","210.6000","13.3663","9.3728","-0.0002","15.3603"
"","211.2000","13.4042","9.3752","-0.0001","15.4336"
"","211.8000","13.4429","9.3857","-0.0001","15.5079"
"","212.4000","13.4804","9.3836","0.0000","15.5807"
"","213.0000","13.5188","9.3939","0.0000","15.6541"
"","213.6000","13.5565","9.4060","-0.0001","15.7258"
"","214.2000","13.5949","9.4272","0.0000","15.7967"
"","214.8000","13.6331","9.4330","0.0001","15.8619"
"","215.4000","13.6712","9.4062","-0.0001","15.8766"
"","216.0000","13.7094","9.4191","0.0000","15.8814"
"","216.6000","13.7469","9.4473","-0.0001","15.8868"
"","217.2000","13.7852","9.4608","0.0000","15.8911"
"","217.8000","13.8238","9.4701","0.0000","15.8955"
"","218.4000","13.8619","9.4754","0.0000","15.8999"
"","219.0000","13.8993","9.4641","0.0000","15.9039"
"","219.6000","13.9378","9.4494","0.0000","15.9372"
"","220.2000","13.9759","9.4551","-0.0001","15.9838"
"","220.8000","14.0144","9.4586","0.0000","16.0191"
"","221.4000","14.0518","9.4242","0.0000","16.0878"
"","222.0000","14.0901","9.4695","0.0001","16.1558"
"","222.6000","14.1282","9.4955","-0.0001","16.2252"
"","223.2000","14.1665","9.5133","-0.0001","16.2952"
"","223.8000","14.2047","9.5229","-0.0002","16.3586"
"","224.4000","14.2427","9.5320","0.0001","16.4150"
"","225.0000","14.2807","9.5116","0.0000","16.4575"
"","225.6000","14.3183","9.4659","-0.0001","16.4603"
"","226.2000","14.3572","9.4665","-0.0001","16.4619"
"","226.8000","14.3951","9.4561","0.0000","16.4623"
"","227.4000","14.4332","9.4626","-0.0001","16.4633"
"","228.0000","14.4708","9.4512","-0.0002","16.4633"
"","228.6000","14.5095","9.4522","0.0000","16.4721"
"","229.2000","14.5475","9.4463","-0.0003","16.4959"
"","229.8000","14.5856","9.4499","0.0000","16.5268"
"","230.4000","14.6234","9.4462","0.0000","16.5642"
"","231.0000","14.6619","9.4519","0.0000","16.6128"
"","231.6000","14.6998","9.4483","0.0000","16.6734"
"","232.2000","14.7379","9.4479","-0.0001","16.7430"
"","232.8000","14.7763","9.4534","-0.0001","16.8156"
"","233.4000","14.8139","9.4527","-0.0002","16.8884"
"","234.0000","14.8524","9.4534","0.0001","16.9627"
"","234.6000","14.8900","9.4456","-0.0001","17.0366"
"","235.2000","14.9289","9.4564","-0.0001","17.1111"
"","235.8000","14.9664","9.4541","0.0000","17.1844"
"","236.4000","15.0044","9.4557","-0.0001","17.2580"
"","237.0000","15.0426","9.4549","0.0000","17.3327"
"","237.6000","15.0812","9.4661","-0.0001","17.4067"
"","238.2000","15.1190","9.4641","0.0001","17.4804"
"","238.8000","15.1567","9.4684","0.0000","17.5534"
"","239.4000","15.1951","9.4722","-0.0001","17.6279"
"","240.0000","15.2333","9.4759","-0.0002","17.7018"
"","240.6000","15.2715","9.4757","-0.0001","17.7764"
"","241.2000","15.3092","9.4734","-0.0001","17.8500"
"","241.8000","15.3475","9.4850","-0.0002","17.9232"
"","242.4000","15.3853","9.4814","-0.0002","17.9972"
"","243.0000","15.4240","9.4879","-0.0002","18.0718"
"","243.6000","15.4618","9.4843","-0.0002","18.1459"
"","244.2000","15.5003","9.4977","0.0001","18.2196"
"","244.8000","15.5376","9.4924","-0.0001","18.2930"
"","245.4000","15.5760","9.4931","-0.0002","18.3674"
"","246.0000","15.6145","9.4950","0.0000","18.4420"
"","246.6000","15.6524","9.5000","-0.0002","18.5155"
"","247.2000","15.6903","9.5054","-0.0001","18.5893"
"","247.8000","15.7280","9.5191","0.0001","18.6610"
"","248.4000","15.7670","9.5559","-0.0001","18.7324"
"","249.0000","15.8047","9.5749","-0.0002","18.8036"
"","249.6000","15.8428","9.5808","-0.0001","18.8768"
"","250.2000","15.8806","9.5823","0.0001","18.9491"
"","250.8000","15.9192","9.5919","0.0001","19.0235"
"","251.4000","15.9569","9.5857","-0.0001","19.0971"
"","252.0000","15.9956","9.5913","-0.0002","19.1717"
"","252.6000","16.0333","9.5884","-0.0002","19.2446"
"","253.2000","16.0713","9.5894","-0.0002","19.3180"
"","253.8000","16.1092","9.5809","-0.0002","19.3923"
"","254.4000","16.1476","9.5826","-0.0001","19.4665"
"","255.0000","16.1861","9.5850","-0.0002","19.5409"
"","255.6000","16.2235","9.5807","-0.0001","19.6139"
"","256.2000","16.2618","9.5799","0.0001","19.6886"
"","256.8000","16.3000","9.5756","-0.0001","19.7631"
"","257.4000","16.3386","9.5796","-0.0001","19.8373"
"","258.0000","16.3758","9.5708","0.0001","19.9107"
"","258.6000","16.4143","9.5754","-0.0002","19.9851"
"","259.2000","16.4522","9.5700","-0.0002","20.0591"
"","259.8000","16.4908","9.5697","0.0000","20.1341"
"","260.4000","16.5286","9.5630","0.0000","20.2078"
"","261.0000","16.5667","9.5677","-0.0002","20.2817"
"","261.6000","16.6047","9.5688","-0.0002","20.3552"
"","262.2000","16.6428","9.5670","0.0000","20.4295"
"","262.8000","16.6811","9.5629","0.0000","20.5047"
"","263.4000","16.7191","9.5646","-0.0002","20.5791"
"","264.0000","16.7574","9.5713","0.0000","20.6531"
"","264.6000","16.7948","9.5612","-0.0001","20.7268"
"","265.2000","16.8336","9.5661","0.0001","20.7934"
"","265.8000","16.8717","9.5645","-0.0001","20.8405"
"","266.4000","16.9099","9.5673","-0.0001","20.8808"
"","267.0000","16.9472","9.5620","-0.0002","20.9152"
"","267.6000","16.9859","9.5706","-0.0002","20.9410"
"","268.2000","17.0240","9.5699","-0.0001","20.9523"
"","268.8000","17.0622","9.5728","-0.0001","20.9636"
"","269.4000","17.1002","9.5757","0.0000","20.9678"
"","270.0000","17.1379","9.5802","0.0001","20.9692"
"","270.6000","17.1763","9.5850","-0.0002","20.9702"
"","271.2000","17.2141","9.5913","0.0001","20.9714"
"","271.8000","17.2529","9.6095","-0.0001","20.9732"
"","272.4000","17.2906","9.6389","-0.0002","20.9748"
"","273.0000","17.3285","9.6844","-0.0001","20.9778"
"","273.6000","17.3664","9.6766","0.0000","20.9781"
"","274.2000","17.4054","9.6822","-0.0003","20.9798"
"","274.8000","17.4429","9.6704","0.0001","20.9806"
"","275.4000","17.4809","9.6707","-0.0002","20.9875"
"","276.0000","17.5189","9.6613","0.0000","21.0096"
"","276.6000","17.5576","9.6611","0.0000","21.0422"
"","277.2000","17.5955","9.6581","0.0000","21.0835"
"","277.8000","17.6333","9.6545","-0.0002","21.1381"
"","278.4000","17.6716","9.6608","-0.0001","21.1985"
"","279.0000","17.7095","9.6577","-0.0001","21.2666"
"","279.6000","17.7480","9.6576","0.0000","21.3401"
"","280.2000","17.7859","9.6540","-0.0002","21.4134"
"","280.8000","17.8243","9.6652","-0.0002","21.4870"
"","281.4000","17.8618","9.6589","-0.0001","21.5602"
"","282.0000","17.9001","9.6593","-0.0002","21.6347"
"","282.6000","17.9383","9.6549","0.0000","21.7094"
"","283.2000","17.9768","9.6634","-0.0001","21.7834"
"","283.8000","18.0142","9.6573","-0.0001","21.8569"
"","284.4000","18.0523","9.6602","0.0001","21.9308"
"","285.0000","18.0908","9.6621","0.0001","22.0061"
"","285.6000","18.1292","9.6635","0.0000","22.0810"
"","286.2000","18.1669","9.6637","-0.0002","22.1544"
"","286.8000","18.2046","9.6655","-0.0001","22.2274"
"","287.4000","18.2434","9.6748","0.0000","22.3019"
"","288.0000","18.2811","9.6659","-0.0002","22.3761"
"","288.6000","18.3197","9.6724","-0.0001","22.4506"
"","289.2000","18.3573","9.6688","0.0000","22.5243"
"","289.8000","18.3955","9.6759","-0.0002","22.5982"
"","290.4000","18.4332","9.6682","-0.0001","22.6722"
"","291.0000","18.4718","9.6719","0.0001","22.7473"
"","291.6000","18.5101","9.6728","-0.0001","22.8219"
"","292.2000","18.5478","9.6761","-0.0002","22.8947"
"","292.8000","18.5857","9.6717","0.0000","22.9694"
"","293.4000","18.6240","9.6748","-0.0001","23.0440"
"","294.0000","18.6626","9.6785","0.0001","23.1191"
"","294.6000","18.7002","9.6767","0.0001","23.1928"
"","295.2000","18.7382","9.6785","-0.0002","23.2669"
"","295.8000","18.7763","9.6740","-0.0003","23.3410"
"","296.4000","18.8150","9.6781","-0.0001","23.4159"
"","297.0000","18.8525","9.6661","-0.0001","23.4901"
"","297.6000","18.8910","9.6680","-0.0001","23.5654"
"","298.2000","18.9287","9.6593","-0.0001","23.6404"
"","298.8000","18.9670","9.6618","-0.0001","23.7154"
"","299.4000","19.0050","9.6240","-0.0001","23.7934"
"","300.0000","19.0433","9.6158","-0.0001","23.8694"
"","300.6000","19.0816","9.6214","-0.0002","23.9442"
"","301.2000","19.1191","9.6053","-0.0001","24.0192"
"","301.8000","19.1575","9.6034","-0.0002","24.0952"
"","302.4000","19.1960","9.6136","0.0001","24.1697"
"","303.0000","19.2340","9.6191","-0.0001","24.2411"
"","303.6000","19.2713","9.5851","0.0000","24.2811"
"","304.2000","19.3099","9.5814","-0.0001","24.2947"
"","304.8000","19.3481","9.5735","0.0001","24.3296"
"","305.4000","19.3864","9.5856","-0.0002","24.3585"
"","306.0000","19.4240","9.5851","0.0001","24.3674"
"","306.6000","19.4623","9.5974","-0.0002","24.3699"
"","307.2000","19.5004","9.5946","0.0001","24.3705"
"","307.8000","19.5384","9.5910","-0.0001","24.3706"
"","308.4000","19.5768","9.5834","-0.0001","24.3706"
"","309.0000","19.6147","9.5961","0.0000","24.3718"
"","309.6000","19.6527","9.6592","-0.0002","24.3764"
"","310.2000","19.6905","9.6759","0.0001","24.3787"
"","310.8000","19.7293","9.6917","0.0000","24.3809"
"","311.4000","19.7672","9.6928","-0.0002","24.3816"
"","312.0000","19.8052","9.6865","-0.0002","24.3818"
"","312.6000","19.8428","9.6782","0.0001","24.3827"
"","313.2000","19.8817","9.6844","-0.0002","24.3964"
"","313.8000","19.9198","9.6780","0.0000","24.4434"
"","314.4000","19.9576","9.6914","-0.0001","24.5035"
"","315.0000","19.9955","9.6925","-0.0001","24.5564"
"","315.6000","20.0337","9.7041","0.0000","24.6145"
"","316.2000","20.0720","9.6964","-0.0002","24.6879"
"","316.8000","20.1100","9.6931","-0.0001","24.7614"
"","317.4000","20.1484","9.6977","0.0001","24.8356"
"","318.0000","20.1860","9.6987","0.0001","24.9087"
"","318.6000","20.2242","9.7032","-0.0002","24.9829"
"","319.2000","20.2622","9.7023","-0.0002","25.0572"
"","319.8000","20.3011","9.7261","-0.0001","25.1302"
"","320.4000","20.3384","9.7280","0.0000","25.2028"
"","321.0000","20.3765","9.7308","-0.0003","25.2767"
"","321.6000","20.4145","9.7311","-0.0002","25.3513"
"","322.2000","20.4533","9.7368","-0.0001","25.4258"
"","322.8000","20.4911","9.7373","-0.0001","25.4988"
"","323.4000","20.5286","9.7389","0.0001","25.5717"
"","324.0000","20.5673","9.7394","0.0000","25.6473"
"","324.6000","20.6053","9.7412","-0.0003","25.7216"
"","325.2000","20.6437","9.7413","-0.0001","25.7969"
"","325.8000","20.6814","9.7407","-0.0001","25.8709"
"","326.4000","20.7198","9.7439","0.0001","25.9451"
"","327.0000","20.7576","9.7380","-0.0002","26.0199"
"","327.6000","20.7959","9.7363","0.0000","26.0951"
"","328.2000","20.8340","9.7336","0.0000","26.1699"
"","328.8000","20.8721","9.7420","-0.0001","26.2435"
"","329.4000","20.9098","9.7347","0.0000","26.3177"
"","330.0000","20.9482","9.7356","-0.0002","26.3928"
"","330.6000","20.9866","9.7354","-0.0001","26.4682"
"","331.2000","21.0244","9.7362","-0.0002","26.5424"
"","331.8000","21.0621","9.7365","0.0000","26.6161"
"","332.4000","21.1003","9.7351","-0.0001","26.6912"
"","333.0000","21.1393","9.7407","0.0000","26.7669"
"","333.6000","21.1768","9.7334","-0.0001","26.8415"
"","334.2000","21.2151","9.7370","0.0000","26.9164"
"","334.8000","21.2526","9.7332","-0.0002","26.9896"
"","335.4000","21.2913","9.7369","-0.0001","27.0657"
"","336.0000","21.3291","9.7281","-0.0001","27.1408"
"","336.6000","21.3675","9.7318","-0.0002","27.2153"
"","337.2000","21.4056","9.7337","-0.0002","27.2892"
"","337.8000","21.4433","9.7321","-0.0002","27.3630"
"","338.4000","21.4814","9.7270","-0.0001","27.4380"
"","339.0000","21.5199","9.7310","0.0001","27.5126"
"","339.6000","21.5582","9.7347","0.0001","27.5872"
"","340.2000","21.5957","9.7320","-0.0003","27.6611"
"","340.8000","21.6339","9.7337","0.0000","27.7358"
"","341.4000","21.6719","9.7285","-0.0001","27.8112"
"","342.0000","21.7108","9.7360","0.0001","27.8866"
"","342.6000","21.7481","9.7269","0.0000","27.9606"
"","343.2000","21.7864","9.7374","0.0001","28.0345"
"","343.8000","21.8243","9.7310","-0.0003","28.1094"
"","344.4000","21.8627","9.7319","-0.0002","28.1701"
"","345.0000","21.9007","9.7298","-0.0001","28.2161"
"","345.6000","21.9389","9.7341","0.0001","28.2558"
"","346.2000","21.9770","9.7380","-0.0002","28.2913"
"","346.8000","22.0147","9.7343","-0.0001","28.3241"
"","347.4000","22.0534","9.7368","-0.0002","28.3548"
"","348.0000","22.0913","9.7432","-0.0001","28.3798"
"","348.6000","22.1294","9.7514","0.0001","28.3972"
"","349.2000","22.1669","9.7489","-0.0002","28.4050"
"","349.8000","22.2056","9.7568","0.0001","28.4081"
"","350.4000","22.2438","9.7586","-0.0001","28.4092"
"","351.0000","22.2818","9.7660","-0.0002","28.4108"
"","351.6000","22.3194","9.7692","-0.0002","28.4118"
"","352.2000","22.3580","9.7876","-0.0003","28.4137"
"","352.8000","22.3961","9.7909","-0.0001","28.4144"
"","353.4000","22.4342","9.8006","0.0000","28.4158"
"","354.0000","22.4722","9.8279","0.0000","28.4181"
"","354.6000","22.5101","9.8816","-0.0002","28.4228"
"","355.2000","22.5484","9.8837","0.0001","28.4250"
"","355.8000","22.5864","9.8504","-0.0002","28.4248"
"","356.4000","22.6250","9.8393","0.0001","28.4257"
"","357.0000","22.6627","9.8161","-0.0002","28.4262"
"","357.6000","22.7007","9.8071","-0.0001","28.4255"
"","358.2000","22.7386","9.7934","0.0001","28.4258"
"","358.8000","22.7776","9.7925","0.0001","28.4412"
"","359.4000","22.8152","9.7823","-0.0003","28.4732"
"","360.0000","22.8530","9.7802","0.0000","28.5059"
"","360.6000","22.8911","9.7755","-0.0001","28.5473"
"","361.2000","22.9297","9.7777","0.0001","28.6018"
"","361.8000","22.9678","9.7734","0.0000","28.6693"
"","362.4000","23.0055","9.7709","0.0001","28.7388"
"","363.0000","23.0437","9.7750","0.0000","28.8120"
"","363.6000","23.0816","9.7710","0.0000","28.8865"
"","364.2000","23.1200","9.7724","0.0000","28.9612"
"","364.8000","23.1580","9.7686","0.0001","29.0357"
"","365.4000","23.1965","9.7805","-0.0002","29.1098"
"","366.0000","23.2339","9.7708","-0.0003","29.1837"
"","366.6000","23.2723","9.7715","-0.0001","29.2582"
"","367.2000","23.3104","9.7701","0.0001","29.3224"
"","367.8000","23.3487","9.7727","0.0001","29.2406"
"","368.4000","23.3863","9.7706","0.0000","29.3017"
"","369.0000","23.4242","9.7665","-0.0001","29.3766"
"","369.6000","23.4631","9.7711","0.0000","29.4526"
"","370.2000","23.5009","9.7684","0.0000","29.5269"
"","370.8000","23.5391","9.7705","-0.0001","29.6021"
"","371.4000","23.5767","9.7699","0.0001","29.6761"
"","372.0000","23.6155","9.7765","0.0000","29.7519"
"","372.6000","23.6532","9.7696","0.0001","29.8271"
"","373.2000","23.6915","9.7733","-0.0001","29.9008"
"","373.8000","23.7293","9.7723","0.0001","29.9751"
"","374.4000","23.7676","9.7782","0.0000","30.0494"
"","375.0000","23.8054","9.7697","-0.0001","30.1249"
"","375.6000","23.8441","9.7725","-0.0001","30.2006"
"","376.2000","23.8821","9.7727","-0.0001","30.2748"
"","376.8000","23.9198","9.7704","-0.0002","30.3488"
"","377.4000","23.9580","9.7700","-0.0002","30.4240"
"","378.0000","23.9959","9.7664","-0.0002","30.4991"
"","378.6000","24.0349","9.7720","0.0000","30.5751"
"","379.2000","24.0722","9.7653","-0.0002","30.6491"
"","379.8000","24.1105","9.7696","-0.0003","30.7240"
"","380.4000","24.1483","9.7679","0.0001","30.7989"
"","381.0000","24.1870","9.7743","0.0001","30.8745"
"","381.6000","24.2249","9.7698","-0.0001","30.9499"
"","382.2000","24.2630","9.7754","0.0001","31.0245"
"","382.8000","24.3009","9.7749","0.0000","31.0993"
"","383.4000","24.3389","9.7739","-0.0002","31.1746"
"","384.0000","24.3772","9.7710","0.0001","31.2503"
"","384.6000","24.4155","9.7770","-0.0001","31.3249"
"","385.2000","24.4535","9.7788","-0.0001","31.3992"
"","385.8000","24.4910","9.7704","-0.0003","31.4737"
"","386.4000","24.5296","9.7724","0.0000","31.5501"
"","387.0000","24.5679","9.7703","-0.0003","31.6259"
"","387.6000","24.6061","9.7752","0.0001","31.7009"
"","388.2000","24.6434","9.7669","-0.0001","31.7753"
"","388.8000","24.6821","9.7723","0.0000","31.8513"
"","389.4000","24.7202","9.7646","-0.0002","31.9273"
"","390.0000","24.7584","9.7569","-0.0001","32.0033"
"","390.6000","24.7961","9.7524","0.0002","32.0784"
"","391.2000","24.8343","9.7549","-0.0001","32.1536"
"","391.8000","24.8727","9.7542","-0.0002","32.2296"
"","392.4000","24.9105","9.7499","-0.0001","32.3040"
"","393.0000","24.9489","9.7542","0.0000","32.3800"
"","393.6000","24.9867","9.7586","-0.0003","32.4541"
"","394.2000","25.0250","9.7621","-0.0001","32.5289"
"","394.8000","25.0628","9.7593","0.0001","32.6018"
"","395.4000","25.1016","9.7653","-0.0001","32.6659"
"","396.0000","25.1392","9.7500","0.0001","32.7045"
"","396.6000","25.1771","9.7540","-0.0003","32.7252"
"","397.2000","25.2150","9.7497","-0.0002","32.7552"
"","397.8000","25.2538","9.7607","-0.0002","32.7778"
"","398.4000","25.2918","9.7580","0.0001","32.7883"
"","399.0000","25.3295","9.7580","-0.0002","32.7923"
"","399.6000","25.3676","9.7664","0.0001","32.7942"
"","400.2000","25.4059","9.7744","-0.0001","32.7952"
"","400.8000","25.4442","9.7794","0.0001","32.7967"
"","401.4000","25.4820","9.7802","0.0001","32.7976"
"","402.0000","25.5205","9.7937","0.0001","32.7996"
"","402.6000","25.5581","9.7961","0.0001","32.8004"
"","403.2000","25.5964","9.8201","-0.0003","32.8030"
"","403.8000","25.6346","9.8681","0.0000","32.8075"
"","404.4000","25.6730","9.8807","0.0001","32.8100"
"","405.0000","25.7104","9.8584","-0.0002","32.8096"
"","405.6000","25.7484","9.8364","-0.0001","32.8086"
"","406.2000","25.7869","9.8226","-0.0001","32.8085"
"","406.8000","25.8253","9.8140","-0.0003","32.8092"
"","407.4000","25.8633","9.8055","-0.0002","32.8146"
"","408.0000","25.9009","9.7999","0.0001","32.8414"
"","408.6000","25.9394","9.7954","0.0001","32.8921"
"","409.2000","25.9774","9.7978","-0.0002","32.9505"
"","409.8000","26.0157","9.7963","0.0001","33.0087"
"","410.4000","26.0535","9.7920","0.0001","33.0764"
"","411.0000","26.0918","9.7956","-0.0003","33.1501"
"","411.6000","26.1294","9.7820","0.0000","33.2254"
"","412.2000","26.1681","9.7846","0.0000","33.2994"
"","412.8000","26.2062","9.7781","0.0001","33.3749"
"","413.4000","26.2443","9.7824","-0.0002","33.4495"
"","414.0000","26.2819","9.7758","-0.0001","33.5245"
"","414.6000","26.3201","9.7747","0.0000","33.6001"
"","415.2000","26.3590","9.7812","-0.0002","33.6762"
"","415.8000","26.3964","9.7792","0.0000","33.7503"
"","416.4000","26.4346","9.7814","-0.0003","33.8252"
"","417.0000","26.4725","9.7783","0.0000","33.9006"
"","417.6000","26.5111","9.7816","-0.0001","33.9768"
"","418.2000","26.5489","9.7744","-0.0001","34.0524"
"","418.8000","26.5870","9.7795","-0.0003","34.1266"
"","419.4000","26.6250","9.7786","0.0000","34.2015"
"","420.0000","26.6633","9.7811","0.0000","34.2769"
"","420.6000","26.7011","9.7707","0.0000","34.3529"
"","421.2000","26.7397","9.7764","-0.0001","34.4286"
"","421.8000","26.7775","9.7762","-0.0002","34.5036"
"","422.4000","26.8152","9.7728","0.0000","34.5786"
"","423.0000","26.8537","9.7717","-0.0001","34.6549"
"","423.6000","26.8920","9.7707","0.0000","34.7304"
"","424.2000","26.9304","9.7702","0.0000","34.8063"
"","424.8000","26.9675","9.7651","-0.0001","34.8802"
"","425.4000","27.0060","9.7670","0.0001","34.9564"
"","426.0000","27.0441","9.7643","0.0000","35.0300"
"","426.6000","27.0827","9.7684","-0.0003","35.1055"
"","427.2000","27.1202","9.7612","0.0000","35.1807"
"","427.8000","27.1585","9.7682","0.0002","35.2556"
"","428.4000","27.1965","9.7654","-0.0001","35.3317"
"","429.0000","27.2348","9.7651","0.0001","35.4071"
"","429.6000","27.2729","9.7639","0.0000","35.4823"
"","430.2000","27.3109","9.7708","-0.0002","35.5568"
"","430.8000","27.3490","9.7724","-0.0003","35.6320"
"","431.4000","27.3865","9.7646","0.0001","35.7070"
"","432.0000","27.4254","9.7709","0.0001","35.7835"
"","432.6000","27.4634","9.7714","-0.0001","35.8585"
"","433.2000","27.5015","9.7771","-0.0001","35.9331"
"","433.8000","27.5390","9.7711","-0.0001","36.0080"
"","434.4000","27.5779","9.7753","0.0000","36.0844"
"","435.0000","27.6159","9.7735","-0.0003","36.1599"
"","435.6000","27.6538","9.7747","0.0000","36.2333"
"","436.2000","27.6918","9.7742","-0.0002","36.3081"
"","436.8000","27.7300","9.7756","-0.0002","36.3835"
"","437.4000","27.7682","9.7725","0.0001","36.4596"
"","438.0000","27.8060","9.7687","0.0000","36.5348"
"","438.6000","27.8445","9.7759","-0.0002","36.6103"
"","439.2000","27.8822","9.7751","0.0001","36.6848"
"","439.8000","27.9206","9.7761","0.0000","36.7601"
"","440.4000","27.9586","9.7715","-0.0002","36.8355"
"","441.0000","27.9971","9.7783","0.0001","36.9110"
"","441.6000","28.0346","9.7773","-0.0002","36.9847"
"","442.2000","28.0728","9.7806","0.0000","37.0598"
"","442.8000","28.1107","9.7746","-0.0001","37.1359"
"","443.4000","28.1496","9.7835","-0.0002","37.2121"
"","444.0000","28.1872","9.7808","-0.0001","37.2867"
"","444.6000","28.2250","9.7801","0.0000","37.3615"
"","445.2000","28.2633","9.7825","0.0001","37.4370"
"","445.8000","28.3016","9.7816","0.0000","37.5129"
"","446.4000","28.3398","9.7829","-0.0002","37.5881"
"","447.0000","28.3773","9.7789","-0.0001","37.6626"
"","447.6000","28.4159","9.7851","0.0000","37.7381"
"","448.2000","28.4536","9.7817","0.0002","37.8126"
"","448.8000","28.4923","9.7826","0.0000","37.8892"
"","449.4000","28.5303","9.7833","0.0000","37.9641"
"","450.0000","28.5684","9.7902","-0.0003","38.0318"
"","450.6000","28.6059","9.7855","-0.0001","38.0910"
"","451.2000","28.6442","9.7872","0.0002","38.1410"
"","451.8000","28.6829","9.7912","0.0001","38.1824"
"","452.4000","28.7209","9.7945","0.0001","38.2170"
"","453.0000","28.7587","9.7988","-0.0002","38.2522"
"","453.6000","28.7964","9.7967","-0.0003","38.2865"
"","454.2000","28.8351","9.8045","-0.0003","38.3197"
"","454.8000","28.8730","9.8048","0.0000","38.3464"
"","455.4000","28.9112","9.8136","-0.0001","38.3652"
"","456.0000","28.9489","9.8153","-0.0002","38.3779"
"","456.6000","28.9876","9.8247","-0.0002","38.3880"
"","457.2000","29.0252","9.8212","-0.0001","38.3973"
"","457.8000","29.0638","9.8136","0.0001","38.4136"
"","458.4000","29.1015","9.7875","0.0000","38.4416"
"","459.0000","29.1395","9.7795","-0.0002","38.4602"
"","459.6000","29.1777","9.7687","0.0001","38.5266"
"","460.2000","29.2160","9.7625","0.0000","38.5992"
"","460.8000","29.2545","9.7636","-0.0002","38.6732"
"","461.4000","29.2918","9.7591","-0.0002","38.7466"
"","462.0000","29.3300","9.7567","0.0001","38.8222"
"","462.6000","29.3683","9.7532","-0.0002","38.8978"
"","463.2000","29.4069","9.7560","0.0003","38.9737"
"","463.8000","29.4442","9.7488","-0.0003","39.0478"
"","464.4000","29.4825","9.7540","-0.0002","39.1228"
"","465.0000","29.5206","9.7484","-0.0002","39.1989"
"","465.6000","29.5592","9.7487","-0.0002","39.2753"
"","466.2000","29.5967","9.7401","-0.0001","39.3507"
"","466.8000","29.6351","9.7470","0.0000","39.4259"
"","467.4000","29.6729","9.7444","-0.0001","39.5015"
"","468.0000","29.7111","9.7406","-0.0003","39.5776"
"","468.6000","29.7496","9.7373","-0.0001","39.6541"
"","469.2000","29.7875","9.7377","0.0002","39.7294"
"","469.8000","29.8256","9.7410","-0.0001","39.8045"
"","470.4000","29.8630","9.7318","0.0001","39.8796"
"","471.0000","29.9019","9.7353","-0.0001","39.9564"
"","471.6000","29.9402","9.7336","-0.0002","40.0322"
"","472.2000","29.9779","9.7345","0.0000","40.1069"
"","472.8000","30.0157","9.7306","0.0002","40.1812"
"","473.4000","30.0541","9.7337","0.0000","40.2570"
"","474.0000","30.0923","9.7290","0.0001","40.3333"
"","474.6000","30.1308","9.7312","0.0000","40.4100"
"","475.2000","30.1684","9.7286","0.0000","40.4850"
"","475.8000","30.2064","9.7292","0.0001","40.5600"
"","476.4000","30.2446","9.7212","0.0002","40.6364"
"","477.0000","30.2827","9.7029","-0.0003","40.7143"
"","477.6000","30.3211","9.7020","0.0001","40.7908"
"","478.2000","30.3589","9.6979","-0.0001","40.8662"
"","478.8000","30.3969","9.6929","-0.0001","40.9420"
"","479.4000","30.4347","9.6806","0.0001","41.0179"
"","480.0000","30.4737","9.6866","-0.0002","41.0941"
"","480.6000","30.5115","9.6815","-0.0002","41.1698"
"","481.2000","30.5492","9.6808","0.0001","41.2446"
"","481.8000","30.5872","9.6737","-0.0001","41.3214"
"","482.4000","30.6258","9.6677","0.0000","41.3989"
"","483.0000","30.6638","9.6588","-0.0002","41.4755"
"","483.6000","30.7016","9.6546","-0.0001","41.5514"
"","484.2000","30.7400","9.6541","-0.0001","41.6277"
"","484.8000","30.7779","9.6465","-0.0001","41.7043"
"","485.4000","30.8163","9.6397","-0.0002","41.7816"
"","486.0000","30.8541","9.6317","-0.0002","41.8579"
"","486.6000","30.8926","9.6339","-0.0001","41.9346"
"","487.2000","30.9299","9.6191","0.0000","42.0104"
"","487.8000","30.9685","9.6155","0.0001","42.0878"
"","488.4000","31.0067","9.6046","-0.0001","42.1651"
"","489.0000","31.0451","9.6051","0.0002","42.2417"
"","489.6000","31.0826","9.5937","-0.0003","42.3184"
"","490.2000","31.1205","9.5830","-0.0002","42.3953"
"","490.8000","31.1591","9.5771","-0.0001","42.4730"
"","491.4000","31.1973","9.5695","0.0000","42.5501"
"","492.0000","31.2353","9.5607","-0.0002","42.6268"
"","492.6000","31.2729","9.5480","-0.0001","42.7018"
"","493.2000","31.3116","9.5427","-0.0001","42.7791"
"","493.8000","31.3492","9.5262","-0.0001","42.8560"
"","494.4000","31.3879","9.5185","0.0000","42.9342"
"","495.0000","31.4255","9.5057","-0.0001","43.0094"
"","495.6000","31.4638","9.4968","0.0001","43.0868"
"","496.2000","31.5015","9.4743","0.0001","43.1646"
"","496.8000","31.5402","9.4655","0.0000","43.2432"
"","497.4000","31.5784","9.4520","0.0001","43.3212"
"","498.0000","31.6166","9.4404","0.0001","43.3989"
"","498.6000","31.6539","9.4130","-0.0002","43.4766"
"","499.2000","31.6923","9.3940","-0.0001","43.5555"
"","499.8000","31.7309","9.3779","-0.0002","43.6344"
"","500.4000","31.7683","9.3488","-0.0002","43.7129"
"","501.0000","31.8068","9.3293","0.0002","43.7922"
"","501.6000","31.8445","9.2948","0.0001","43.8716"
"","502.2000","31.8833","9.2643","0.0001","43.9528"
"","502.8000","31.9207","9.2223","-0.0002","44.0327"
"","503.4000","31.9593","9.1866","0.0001","44.1140"
"","504.0000","31.9971","9.1373","-0.0001","44.1955"
"","504.6000","32.0353","9.0792","-0.0002","44.2789"
"","505.2000","32.0735","9.0070","0.0000","44.3640"
"","505.8000","32.1115","8.9309","0.0001","44.4507"
"","506.4000","32.1499","8.8430","-0.0001","44.5383"
"","507.0000","32.1873","8.7247","0.0001","44.6266"
"","507.6000","32.2259","8.5830","-0.0003","44.7157"
"","508.2000","32.2642","8.3853","-0.0002","44.8177"
"","508.3310","32.2724","4.8677","0.0001","44.6141"